Workbook

Sheet SUMMARY
B1: ELECT | O1: COMBINED LOBBYWISE RUNNING STAFF POSITION
A2: CATEGORY | B2: North | C2: South | D2: KOAA | E2: DDJ+MJT | F2: NH | G2: BT | H2: RHA | I2: CP | J2: NKG | K2: HQ | L2: TOTAL
A3: LPM | B3: =COUNTIF(North!C:C,"LPM") -> 23 | C3: =COUNTIF(South!C:C,"LPM") -> 0 | D3: =COUNTIF(KOAA!C:C,"LPM") -> 27 | E3: =COUNTIF(DDJ!C:C,"LPM") -> 0 | F3: =COUNTIF(NH!C:C,"LPM") -> 0 | G3: =COUNTIF(BT!C:C,"LPM") -> 0 | H3: =COUNTIF(RHA!C:C,"LPM") -> 0 | I3: 0 | J3: 0 | K3: 0 | L3: =SUM(B3:K3) -> 50 | O3: Category | P3: North | Q3: South | R3: KOAA | S3: DDJ+KRP | T3: NH | U3: BT | V3: RHA | W3: Total
A4: Motorman | B4: =COUNTIF(North!C:C,"MOTORMAN") -> 151 | C4: =COUNTIF(South!C:C,"MOTORMAN") -> 133 | D4: =COUNTIF(KOAA!C:C,"MOTORMAN") -> 0 | E4: =COUNTIF(DDJ!C:C,"MOTORMAN") -> 0 | F4: =COUNTIF(NH!C:C,"MOTORMAN") -> 55 | G4: =COUNTIF(BT!C:C,"Motorman") -> 49 | H4: =COUNTIF(RHA!C:C,"MOTORMAN") -> 46 | I4: 0 | J4: 0 | K4: 0 | L4: =SUM(B4:K4) -> 434 | O4: LPM | P4: =SUM(B3,B19,B29) -> 39 | Q4: =SUM(C3,C19,C29) -> 0 | R4: =SUM(D3,D19,D29) -> 28 | S4: =SUM(E3,E19,E29) -> 0 | T4: =SUM(F3,F19,F29) -> 0 | U4: =SUM(G3,G19,G29) -> 0 | V4: =SUM(H3,H19,H29) -> 0 | W4: =SUM(P4:V4) -> 67
A5: LPP(Loco) | B5: =COUNTIF(North!C:C,"LPP(Loco)") -> 11 | C5: =COUNTIF(South!C:C,"LPP(Loco)") -> 0 | D5: =COUNTIF(KOAA!C:C,"LPP(Loco)") -> 0 | E5: =COUNTIF(DDJ!C:C,"LPP(Loco)") -> 0 | F5: =COUNTIF(NH!C:C,"LPP(Loco)") -> 0 | G5: =COUNTIF(BT!C:C,"LPP(Loco)") -> 0 | H5: =COUNTIF(RHA!C:C,"LPP(LOCO)") -> 0 | I5: 0 | J5: 0 | K5: 0 | L5: =SUM(B5:K5) -> 11 | O5: Motorman | P5: =SUM(B4,B20,B30) -> 160 | Q5: =SUM(C4,C20,C30) -> 145 | R5: =SUM(D4,D20,D30) -> 0 | S5: =SUM(E4,E20,E30) -> 0 | T5: =SUM(F4,F20,F30) -> 56 | U5: =SUM(G4,G20,G30) -> 49 | V5: =SUM(H4,H20,H30) -> 48 | W5: =SUM(P5:V5) -> 458
A6: LPG | B6: =COUNTIF(North!C:C,"LPG") -> 19 | C6: =COUNTIF(South!C:C,"LPG") -> 5 | D6: =COUNTIF(KOAA!C:C,"LPG") -> 0 | E6: =COUNTIF(DDJ!C:C,"LPG") -> 65 | F6: =COUNTIF(NH!C:C,"LPG") -> 12 | G6: =COUNTIF(BT!C:C,"LPG") -> 7 | H6: =COUNTIF(RHA!C:C,"LPG") -> 28 | I6: 0 | J6: 0 | K6: 0 | L6: =SUM(B6:K6) -> 136 | O6: LPP(Loco) | P6: =SUM(B5,B21,B31) -> 14 | Q6: =SUM(C5,C21,C31) -> 0 | R6: =SUM(D5,D21,D31) -> 0 | S6: =SUM(E5,E21,E31) -> 0 | T6: =SUM(F5,F21,F31) -> 0 | U6: =SUM(G5,G21,G31) -> 0 | V6: =SUM(H5,H21,H31) -> 0 | W6: =SUM(P6:V6) -> 14
A7: LPS | B7: =COUNTIF(North!C:C,"LPS") -> 56 | C7: =COUNTIF(South!C:C,"LPS") -> 24 | D7: =COUNTIF(KOAA!C:C,"LPS") -> 25 | E7: =COUNTIF(DDJ!C:C,"LPS") -> 10 | F7: =COUNTIF(NH!C:C,"LPS") -> 13 | G7: =COUNTIF(BT!C:C,"LPS") -> 11 | H7: =COUNTIF(RHA!C:C,"LPS") -> 17 | I7: 0 | J7: 0 | K7: 0 | L7: =SUM(B7:K7) -> 156 | O7: LPG | P7: =SUM(B6,B22,B32) -> 21 | Q7: =SUM(C6,C22,C32) -> 6 | R7: =SUM(D6,D22,D32) -> 0 | S7: =SUM(E6,E22,E32) -> 165 | T7: =SUM(F6,F22,F32) -> 45 | U7: =SUM(G6,G22,G32) -> 9 | V7: =SUM(H6,H22,H32) -> 47 | W7: =SUM(P7:V7) -> 293
A8: ALP | B8: =COUNTIF(North!C:C,"ALP") -> 62 | C8: =COUNTIF(South!C:C,"ALP") -> 0 | D8: =COUNTIF(KOAA!C:C,"ALP") -> 16 | E8: =COUNTIF(DDJ!C:C,"ALP") -> 78 | F8: =COUNTIF(NH!C:C,"ALP") -> 30 | G8: =COUNTIF(BT!C:C,"ALP") -> 0 | H8: =COUNTIF(RHA!C:C,"ALP") -> 24 | I8: 0 | J8: 0 | K8: 0 | L8: =SUM(B8:K8) -> 210 | O8: LPS | P8: =SUM(B7,B23,B33) -> 65 | Q8: =SUM(C7,C23,C33) -> 26 | R8: =SUM(D7,D23,D33) -> 37 | S8: =SUM(E7,E23,E33) -> 16 | T8: =SUM(F7,F23,F33) -> 26 | U8: =SUM(G7,G23,G33) -> 15 | V8: =SUM(H7,H23,H33) -> 26 | W8: =SUM(P8:V8) -> 211
A9: Total | B9: =SUM(B3:B8) -> 322 | C9: =SUM(C3:C8) -> 162 | D9: =SUM(D3:D8) -> 68 | E9: =SUM(E3:E8) -> 153 | F9: =SUM(F3:F8) -> 110 | G9: =SUM(G3:G8) -> 67 | H9: =SUM(H3:H8) -> 115 | I9: =SUM(I3:I8) -> 0 | ... L9: =SUM(L3:L8) -> 997 | O9: ALP | P9: =SUM(B8,B24,B34) -> 88 | Q9: =SUM(C8,C24,C34) -> 0 | R9: =SUM(D8,D24,D34) -> 32 | S9: =SUM(E8,E24,E34) -> 127 | T9: =SUM(F8,F24,F34) -> 45 | U9: =SUM(G8,G24,G34) -> 0 | V9: =SUM(H8,H24,H34) -> 45 | W9: =SUM(P9:V9) -> 337
A10: CLI | B10: =COUNTIF(SUPV!F:F,"CLI") -> 36 | C10: 0 | D10: 0 | E10: 0 | F10: 0 | G10: 0 | H10: 0 | I10: 0 | J10: 0 | K10: 0 | L10: =SUM(B10:K10) -> 36 | O10: Total | P10: =SUM(B9,B25,B35) -> 387 | Q10: =SUM(C9,C25,C35) -> 177 | R10: =SUM(D9,D25,D35) -> 97 | S10: =SUM(E9,E25,E35) -> 308 | T10: =SUM(F9,F25,F35) -> 172 | U10: =SUM(G9,G25,G35) -> 73 | V10: =SUM(H9,H25,H35) -> 166 | W10: =SUM(P10:V10) -> 1380
A11: DRAFTED & De cat | B11: =COUNTIF(SUPV!I:I,"CC(R) NORTH") -> 12 | C11: =COUNTIF(SUPV!I:I,"CC(R) SOUTH") -> 3 | D11: =COUNTIF(SUPV!I:I,"CC(R) KOAA") -> 2 | E11: =COUNTIF(SUPV!I:I,"CC(R) DDJ") -> 6 | F11: =COUNTIF(SUPV!I:I,"CC(R) NH") -> 4 | G11: =COUNTIF(SUPV!I:I,"CC(R) BT") -> 5 | H11: =COUNTIF(SUPV!I:I,"CC(R) RHA") -> 4 | I11: 0 | J11: 0 | K11: 0 | L11: =SUM(B11:K11) -> 36
A12: MINISTERIAL | B12: =COUNTIFS(Ministerial!H:H,"CC(R) NORTH") -> 10 | C12: =COUNTIFS(Ministerial!H:H,"CC(R) SOUTH") -> 0 | D12: =COUNTIFS(Ministerial!H:H,"CC(R) KOAA") -> 0 | E12: =COUNTIFS(Ministerial!H:H,"CC(R) DDJ") -> 8 | F12: =COUNTIFS(Ministerial!H:H,"CC(R) NH") -> 2 | G12: =COUNTIFS(Ministerial!H:H,"CC(R) BT") -> 0 | H12: =COUNTIFS(Ministerial!H:H,"CC(R) RHA") -> 0 | I12: 0 | J12: =COUNTIF(Ministerial!H:H,"CP") -> 0 | K12: =COUNTIF(Ministerial!H:H,"HQ") -> 14 | L12: =SUM(B12:K12) -> 34
A13: Technical | B13: 0 | C13: 0 | D13: 0 | E13: 0 | F13: 0 | G13: 0 | H13: 0 | I13: =COUNTIF('Trip Shed'!E:E,"CP") -> 31 | J13: =COUNTIF('Trip Shed'!E:E,"NKG") -> 45 | K13: 0 | L13: =SUM(B13:K13) -> 76
A14: GR TOTAL | B14: =SUM(B9:B13) -> 380 | C14: =SUM(C9:C13) -> 165 | D14: =SUM(D9:D13) -> 70 | E14: =SUM(E9:E13) -> 167 | F14: =SUM(F9:F13) -> 116 | G14: =SUM(G9:G13) -> 72 | H14: =SUM(H9:H13) -> 119 | I14: =SUM(I9:I13) -> 31 | ... L14: =SUM(L9:L13) -> 1179
A15: 24 Nos ALP working at DSL wing included in MOR and 01 nos ALP promoted to LPS shown in ALP, Total=4 Nos MTM(01 no. MTM in MLDT Div & 03 nos. MTM working as LPP/Loco) included in NORTH MOR. | O15: lobby | P15: LPM | Q15: LPP(L) | R15: MOTORMAN | S15: LPG | T15: LPS | U15: ALP | V15: Total
O16: NORTH | P16: =SUM(COUNTIFS(North!C:C,"lpm",North!F:F,"F"),COUNTIFS(CONV!C:C,"lpm",CONV!F:F,"f")) -> 0 | Q16: =SUM(COUNTIFS(North!C:C,"lpP(LOCO)",North!F:F,"F"),COUNTIFS(CONV!C:C,"LPP(Loco)",CONV!F:F,"f")) -> 0 | R16: =SUM(COUNTIFS(North!C:C,"MOTORMAN",North!F:F,"F"),COUNTIFS(CONV!C:C,"motorman",CONV!K:K,"CC(R) north",CONV!F:F,"F")) -> 6 | S16: =SUM(COUNTIFS(North!C:C,"lpg",North!F:F,"F"),COUNTIFS(CONV!C:C,"lpg",CONV!K:K,"CC(R) north",CONV!F:F,"F")) -> 0 | T16: =SUM(COUNTIFS(North!C:C,"LPS",North!F:F,"F"),COUNTIFS(CONV!C:C,"lps",CONV!K:K,"cc(r) north",CONV!F:F,"f")) -> 6 | U16: =SUM(COUNTIFS(North!C:C,"alp",North!F:F,"F"),COUNTIFS(CONV!C:C,"alp",CONV!K:K,"cc(r) north",CONV!F:F,"f")) -> 6 | V16: =SUM(P16:U16) -> 18
A17: ON ROll | B17: CONV | O17: SOUTH | P17: =SUM(COUNTIFS(South!C:C,"lpm",South!F:F,"F"),COUNTIFS(CONV!C:C,"lpm",CONV!F:F,"f")) -> 0 | Q17: =SUM(COUNTIFS(South!C:C,"lpP(LOCO)",South!F:F,"F"),COUNTIFS(CONV!C:C,"LPP(Loco)",CONV!F:F,"f")) -> 0 | R17: =SUM(COUNTIFS(South!C:C,"MOTORMAN",South!F:F,"F"),COUNTIFS(CONV!C:C,"motorman",CONV!K:K,"CC(R) SOUTH",CONV!F:F,"F")) -> 6 | S17: =SUM(COUNTIFS(South!C:C,"lpg",South!F:F,"F"),COUNTIFS(CONV!C:C,"lpg",CONV!K:K,"CC(R) SOUTH",CONV!F:F,"F")) -> 0 | T17: =SUM(COUNTIFS(South!C:C,"LPS",South!F:F,"F"),COUNTIFS(CONV!C:C,"lps",CONV!K:K,"cc(r) south",CONV!F:F,"f")) -> 2 | U17: =SUM(COUNTIFS(South!C:C,"alp",South!F:F,"F"),COUNTIFS(CONV!C:C,"alp",CONV!K:K,"cc(r) south",CONV!F:F,"f")) -> 0 | V17: =SUM(P17:U17) -> 8
B18: North | C18: South | D18: KOAA | E18: DDJ+KRP | F18: NH | G18: BT | H18: RHA | I18: Total | O18: KOAA | P18: =SUM(COUNTIFS(KOAA!C:C,"lpm",KOAA!F:F,"F"),COUNTIFS(CONV!C:C,"lpm",CONV!F:F,"f")) -> 0 | Q18: =SUM(COUNTIFS(South!C:C,"lpP(LOCO)",South!F:F,"F"),COUNTIFS(CONV!C:C,"LPP(Loco)",CONV!F:F,"f")) -> 0 | R18: =SUM(COUNTIFS(KOAA!C:C,"MOTORMAN",KOAA!F:F,"F"),COUNTIFS(CONV!C:C,"motorman",CONV!F:F,"f")) -> 0 | S18: =SUM(COUNTIFS(KOAA!C:C,"lpg",KOAA!F:F,"F"),COUNTIFS(CONV!C:C,"lpg",CONV!K:K,"CC(R) koaa",CONV!F:F,"F")) -> 0 | T18: =SUM(COUNTIFS(KOAA!C:C,"LPS",KOAA!F:F,"F"),COUNTIFS(CONV!C:C,"lps",CONV!K:K,"cc(r) koaa",CONV!F:F,"f")) -> 2 | U18: =SUM(COUNTIFS(KOAA!C:C,"alp",KOAA!F:F,"F"),COUNTIFS(CONV!C:C,"alp",CONV!K:K,"cc(r) koaa",CONV!F:F,"f")) -> 1 | V18: =SUM(P18:U18) -> 3
A19: LPM | B19: =COUNTIFS(CONV!C:C,"LPM",CONV!K:K,"CC(R) NORTH",CONV!R:R,"Elect") -> 16 | C19: =COUNTIFS(CONV!C:C,"LPM",CONV!K:K,"CC(R) South") -> 0 | D19: =COUNTIFS(CONV!C:C,"LPM",CONV!K:K,"CC(R) KOAA",CONV!R:R,"Elect") -> 1 | E19: =COUNTIFS(CONV!C:C,"LPM",CONV!K:K,"CC(R) DDJ") -> 0 | F19: =COUNTIFS(CONV!C:C,"LPM",CONV!K:K,"CC(R) NH") -> 0 | G19: =COUNTIFS(CONV!C:C,"LPM",CONV!K:K,"CC(R) BT") -> 0 | H19: =COUNTIFS(CONV!C:C,"LPM",CONV!K:K,"CC(R) RHA") -> 0 | I19: =SUM(B19:H19) -> 17 | O19: DDJ | P19: =SUM(COUNTIFS(DDJ!C:C,"lpm",DDJ!F:F,"F"),COUNTIFS(CONV!C:C,"lpm",CONV!F:F,"f")) -> 0 | Q19: =SUM(COUNTIFS(DDJ!C:C,"lpP(LOCO)",DDJ!F:F,"F"),COUNTIFS(CONV!C:C,"LPP(Loco)",CONV!F:F,"f")) -> 0 | R19: =SUM(COUNTIFS(DDJ!C:C,"MOTORMAN",DDJ!F:F,"F"),COUNTIFS(CONV!C:C,"motorman",CONV!F:F,"f")) -> 0 | S19: =SUM(COUNTIFS(DDJ!C:C,"lpg",DDJ!F:F,"F"),COUNTIFS(CONV!C:C,"lpg",CONV!K:K,"CC(R) ddj",CONV!F:F,"F")) -> 2 | T19: =SUM(COUNTIFS(DDJ!C:C,"LPS",DDJ!F:F,"F"),COUNTIFS(CONV!C:C,"lps",CONV!K:K,"cc(r) ddj",CONV!F:F,"f")) -> 1 | U19: =SUM(COUNTIFS(DDJ!C:C,"alp",DDJ!F:F,"F"),COUNTIFS(CONV!C:C,"alp",CONV!K:K,"cc(r) ddj",CONV!F:F,"f")) -> 7 | V19: =SUM(P19:U19) -> 10
A20: Motorman | B20: =COUNTIFS(CONV!C:C,"MOTORMAN",CONV!K:K,"CC(R) NORTH",CONV!R:R,"Elect") -> 9 | C20: =COUNTIFS(CONV!C:C,"motorman",CONV!K:K,"CC(R) South",CONV!R:R,"Elect") -> 12 | D20: =COUNTIFS(CONV!C:C,"MOTORMAN",CONV!K:K,"CC(R) KOAA",CONV!R:R,"Elect") -> 0 | E20: =COUNTIFS(CONV!C:C,"MOTORMAN",CONV!K:K,"CC(R) DDJ",CONV!R:R,"Elect") -> 0 | F20: =COUNTIFS(CONV!C:C,"MOTORMAN",CONV!K:K,"CC(R) NH",CONV!R:R,"Elect") -> 1 | G20: =COUNTIFS(CONV!C:C,"MOTORMAN",CONV!K:K,"CC(R) BT",CONV!R:R,"Elect") -> 0 | H20: =COUNTIFS(CONV!C:C,"MOTORMAN",CONV!K:K,"CC(R) RHA",CONV!R:R,"Elect") -> 2 | I20: =SUM(B20:H20) -> 24 | O20: NH | P20: =SUM(COUNTIFS(NH!C:C,"lpm",NH!F:F,"F"),COUNTIFS(CONV!C:C,"lpm",CONV!F:F,"f")) -> 0 | Q20: =SUM(COUNTIFS(NH!C:C,"lpP(LOCO)",NH!F:F,"F"),COUNTIFS(CONV!C:C,"LPP(Loco)",CONV!F:F,"f")) -> 0 | R20: =SUM(COUNTIFS(NH!C:C,"MOTORMAN",NH!F:F,"F"),COUNTIFS(CONV!C:C,"motorman",CONV!K:K,"CC(R) nh",CONV!F:F,"F")) -> 1 | S20: =SUM(COUNTIFS(NH!C:C,"lpg",NH!F:F,"F"),COUNTIFS(CONV!C:C,"lpg",CONV!K:K,"CC(R) nh",CONV!F:F,"F")) -> 2 | T20: =SUM(COUNTIFS(NH!C:C,"LPS",NH!F:F,"F"),COUNTIFS(CONV!C:C,"lps",CONV!K:K,"cc(r) nh",CONV!F:F,"f")) -> 0 | U20: =SUM(COUNTIFS(NH!C:C,"alp",NH!F:F,"F"),COUNTIFS(CONV!C:C,"alp",CONV!K:K,"cc(r) nh",CONV!F:F,"f")) -> 3 | V20: =SUM(P20:U20) -> 6
A21: LPP(Loco) | B21: =COUNTIFS(CONV!C:C,"LPP(LOCO)",CONV!K:K,"CC(R) NORTH",CONV!R:R,"Elect") -> 3 | C21: =COUNTIFS(CONV!C:C,"LPP(loco)",CONV!K:K,"CC(R) South",CONV!R:R,"Elect") -> 0 | D21: =COUNTIFS(CONV!C:C,"LPP(LOCO)",CONV!K:K,"CC(R) KOAA",CONV!R:R,"Elect") -> 0 | E21: =COUNTIFS(CONV!C:C,"LPP(LOCO)",CONV!K:K,"CC(R) DDJ",CONV!R:R,"Elect") -> 0 | F21: =COUNTIFS(CONV!C:C,"LPP(LOCO)",CONV!K:K,"CC(R) NH",CONV!R:R,"Elect") -> 0 | G21: =COUNTIFS(CONV!C:C,"LPP(LOCO)",CONV!K:K,"CC(R) BT",CONV!R:R,"Elect") -> 0 | H21: =COUNTIFS(CONV!C:C,"LPP(LOCO)",CONV!K:K,"CC(R) RHA",CONV!R:R,"Elect") -> 0 | I21: =SUM(B21:H21) -> 3 | O21: RHA | P21: =SUM(COUNTIFS(RHA!C:C,"lpm",RHA!F:F,"F"),COUNTIFS(CONV!C:C,"lpm",CONV!F:F,"f")) -> 0 | Q21: =SUM(COUNTIFS(RHA!C:C,"lpP(LOCO)",RHA!F:F,"F"),COUNTIFS(CONV!C:C,"LPP(Loco)",CONV!F:F,"f")) -> 0 | R21: =SUM(COUNTIFS(RHA!C:C,"MOTORMAN",RHA!F:F,"F"),COUNTIFS(CONV!C:C,"motorman",CONV!K:K,"CC(R) rha",CONV!F:F,"F")) -> 0 | S21: =SUM(COUNTIFS(RHA!C:C,"lpg",RHA!F:F,"F"),COUNTIFS(CONV!C:C,"lpg",CONV!K:K,"CC(R) rha",CONV!F:F,"F")) -> 3 | T21: =SUM(COUNTIFS(RHA!C:C,"LPS",RHA!F:F,"F"),COUNTIFS(CONV!C:C,"lps",CONV!K:K,"cc(r) rha",CONV!F:F,"f")) -> 0 | U21: =SUM(COUNTIFS(RHA!C:C,"alp",RHA!F:F,"F"),COUNTIFS(CONV!C:C,"alp",CONV!K:K,"cc(r) rha",CONV!F:F,"f")) -> 1 | V21: =SUM(P21:U21) -> 4
A22: LPG | B22: =COUNTIFS(CONV!C:C,"LPG",CONV!K:K,"CC(R) NORTH",CONV!R:R,"Elect") -> 2 | C22: =COUNTIFS(CONV!C:C,"LPG",CONV!K:K,"CC(R) South",CONV!R:R,"Elect") -> 1 | D22: =COUNTIFS(CONV!C:C,"LPG",CONV!K:K,"CC(R) KOAA",CONV!R:R,"Elect") -> 0 | E22: =COUNTIFS(CONV!C:C,"LPG",CONV!K:K,"CC(R) DDJ",CONV!R:R,"Elect") -> 23 | F22: =COUNTIFS(CONV!C:C,"LPG",CONV!K:K,"CC(R) NH",CONV!R:R,"Elect") -> 12 | G22: =COUNTIFS(CONV!C:C,"LPG",CONV!K:K,"CC(R) BT",CONV!R:R,"Elect") -> 2 | H22: =COUNTIFS(CONV!C:C,"LPG",CONV!K:K,"CC(R) RHA",CONV!R:R,"Elect") -> 6 | I22: =SUM(B22:H22) -> 46 | O22: BT | P22: =SUM(COUNTIFS(BT!C:C,"lpm",BT!F:F,"F"),COUNTIFS(CONV!C:C,"lpm",CONV!F:F,"f")) -> 0 | Q22: =SUM(COUNTIFS(BT!C:C,"lpP(LOCO)",BT!F:F,"F"),COUNTIFS(CONV!C:C,"LPP(Loco)",CONV!F:F,"f")) -> 0 | R22: =SUM(COUNTIFS(BT!C:C,"MOTORMAN",BT!F:F,"F"),COUNTIFS(CONV!C:C,"motorman",CONV!K:K,"CC(R) bt",CONV!F:F,"F")) -> 0 | S22: =SUM(COUNTIFS(BT!C:C,"lpg",BT!F:F,"F"),COUNTIFS(CONV!C:C,"lpg",CONV!K:K,"CC(R) bt",CONV!F:F,"F")) -> 0 | T22: =SUM(COUNTIFS(BT!C:C,"LPS",BT!F:F,"F"),COUNTIFS(CONV!C:C,"lps",CONV!K:K,"cc(r) bt",CONV!F:F,"f")) -> 0 | U22: =SUM(COUNTIFS(BT!C:C,"alp",BT!F:F,"F"),COUNTIFS(CONV!C:C,"alp",CONV!K:K,"cc(r) bt",CONV!F:F,"f")) -> 0 | V22: =SUM(P22:U22) -> 0
A23: LPS | B23: =COUNTIFS(CONV!C:C,"LPS",CONV!K:K,"CC(R) NORTH",CONV!R:R,"Elect") -> 9 | C23: =COUNTIFS(CONV!C:C,"LPS",CONV!K:K,"CC(R) South",CONV!R:R,"Elect") -> 2 | D23: =COUNTIFS(CONV!C:C,"LPS",CONV!K:K,"CC(R) KOAA",CONV!R:R,"Elect") -> 10 | E23: =COUNTIFS(CONV!C:C,"LPS",CONV!K:K,"CC(R) DDJ",CONV!R:R,"Elect") -> 1 | F23: =COUNTIFS(CONV!C:C,"LPS",CONV!K:K,"CC(R) NH",CONV!R:R,"Elect") -> 7 | G23: =COUNTIFS(CONV!C:C,"LPS",CONV!K:K,"CC(R) BT",CONV!R:R,"Elect") -> 4 | H23: =COUNTIFS(CONV!C:C,"LPS",CONV!K:K,"CC(R) RHA",CONV!R:R,"Elect") -> 5 | I23: =SUM(B23:H23) -> 38 | O23: Total | P23: =SUM(P16:P22) -> 0 | Q23: =SUM(Q16:Q22) -> 0 | R23: =SUM(R16:R22) -> 13 | S23: =SUM(S16:S22) -> 7 | T23: =SUM(T16:T22) -> 11 | U23: =SUM(U16:U22) -> 18 | V23: =SUM(V16:V22) -> 49
A24: ALP | B24: =COUNTIFS(CONV!C:C,"ALP",CONV!K:K,"CC(R) NORTH",CONV!R:R,"Elect") -> 26 | C24: =COUNTIFS(CONV!C:C,"ALP",CONV!K:K,"CC(R) South",CONV!R:R,"Elect") -> 0 | D24: =COUNTIFS(CONV!C:C,"ALP",CONV!K:K,"CC(R) KOAA",CONV!R:R,"Elect") -> 16 | E24: =COUNTIFS(CONV!C:C,"ALP",CONV!K:K,"CC(R) DDJ",CONV!R:R,"Elect") -> 10 | F24: =COUNTIFS(CONV!C:C,"ALP",CONV!K:K,"CC(R) NH",CONV!R:R,"Elect") -> 4 | G24: =COUNTIFS(CONV!C:C,"ALP",CONV!K:K,"CC(R) BT",CONV!R:R,"Elect") -> 0 | H24: =COUNTIFS(CONV!C:C,"ALP",CONV!K:K,"CC(R) RHA",CONV!R:R,"Elect") -> 10 | I24: =SUM(B24:H24) -> 66
A25: Total | B25: =SUM(B19:B24) -> 65 | C25: =SUM(C19:C24) -> 15 | D25: =SUM(D19:D24) -> 27 | E25: =SUM(E19:E24) -> 34 | F25: =SUM(F19:F24) -> 24 | G25: =SUM(G19:G24) -> 6 | H25: =SUM(H19:H24) -> 23 | I25: =SUM(B25:H25) -> 194
A27: ON ROll | B27: DSL | O27: Distribution of Running Staff under CLI | Y27: DT | Z27: =TODAY() -> 46099
B28: North | C28: South | D28: KOAA | E28: DDJ+KRP | F28: NH | G28: BT | H28: RHA | I28: Total | O28: SL | P28: CLI | Q28: LPM | R28: LPP(Loco) | S28: MOTORMAN | T28: LPG | U28: LPS | V28: ALP | W28: TWD | X28: TOTAL | Y28: LP
A29: LPM | B29: =COUNTIFS(CONV!C:C,"LPM",CONV!K:K,"CC(R) NORTH",CONV!R:R,"DSL") -> 0 | C29: =COUNTIFS(CONV!C:C,"LPM",CONV!K:K,"CC(R) South",CONV!R:R,"DSL") -> 0 | D29: =COUNTIFS(CONV!C:C,"LPM",CONV!K:K,"CC(R) KOAA",CONV!R:R,"DSL") -> 0 | E29: =COUNTIFS(CONV!C:C,"LPM",CONV!K:K,"CC(R) DDJ") -> 0 | F29: =COUNTIFS(CONV!C:C,"LPM",CONV!K:K,"CC(R) NH") -> 0 | G29: =COUNTIFS(CONV!C:C,"LPM",CONV!K:K,"CC(R) BT") -> 0 | H29: =COUNTIFS(CONV!C:C,"LPM",CONV!K:K,"CC(R) RHA") -> 0 | I29: =SUM(B29:H29) -> 0 | O29: 1 | P29: AMITAV TARAFDER | Q29: =SUM(COUNTIFS(North!C:C,"LPM",North!L:L,"AMITAV TARAFDER"),COUNTIFS(KOAA!C:C,"LPM",KOAA!L:L,"AMITAV TARAFDER"),COUNTIFS(South!C:C,"LPM",South!L:L,"AMITAV TARAFDER"),COUNTIFS(DDJ!C:C,"LPM",DDJ!L:L,"AMITAV TARAFDER"),COUNTIFS(BT!C:C,"LPM",BT!L:L,"AMITAV TARAFDER"),COUNTIFS(NH!C:C,"LPM",NH!L:L,"AMITAV TARAFDER"),COUNTIFS(CONV!C:C,"LPM",CONV!L:L,"AMITAV TARAFDER")) -> 0 | R29: =SUM(COUNTIFS(North!C:C,"LPP(LOCO)",North!L:L,"AMITAV TARAFDER"),COUNTIFS(KOAA!C:C,"LPP(LOCO)",KOAA!L:L,"AMITAV TARAFDER"),COUNTIFS(South!C:C,"LPP(LOCO)",South!L:L,"AMITAV TARAFDER"),COUNTIFS(DDJ!C:C,"LPP(LOCO)",DDJ!L:L,"AMITAV TARAFDER"),COUNTIFS(BT!C:C,"LPP(LOCO)",BT!L:L,"AMITAV TARAFDER"),COUNTIFS(NH!C:C,"LPP(LOCO)",NH!L:L,"AMITAV TARAFDER"),COUNTIFS(CONV!C:C,"LPP(LOCO)",CONV!L:L,"AMITAV TARAFDER")) -> 0 | S29: =SUM(COUNTIFS(North!C:C,"Motorman",North!L:L,"AMITAV TARAFDER"),COUNTIFS(KOAA!C:C,"Motorman",KOAA!L:L,"AMITAV TARAFDER"),COUNTIFS(South!C:C,"Motorman",South!L:L,"AMITAV TARAFDER"),COUNTIFS(DDJ!C:C,"Motorman",DDJ!L:L,"AMITAV TARAFDER"),COUNTIFS(BT!C:C,"Motorman",BT!L:L,"AMITAV TARAFDER"),COUNTIFS(NH!C:C,"Motorman",NH!L:L,"AMITAV TARAFDER"),COUNTIFS(CONV!C:C,"MOTORMAN",CONV!L:L,"AMITAV TARAFDER"),COUNTIFS(RHA!C:C,"MOTORMAN",RHA!L:L,"AMITAV TARAFDER")) -> 36 | T29: =SUM(COUNTIFS(North!C:C,"LPG",North!L:L,"AMITAV TARAFDER"),COUNTIFS(KOAA!C:C,"LPG",KOAA!L:L,"AMITAV TARAFDER"),COUNTIFS(South!C:C,"LPG",South!L:L,"AMITAV TARAFDER"),COUNTIFS(DDJ!C:C,"LPG",DDJ!L:L,"AMITAV TARAFDER"),COUNTIFS(BT!C:C,"LPG",BT!L:L,"AMITAV TARAFDER"),COUNTIFS(NH!C:C,"LPG",NH!L:L,"AMITAV TARAFDER"),COUNTIFS(CONV!C:C,"LPG",CONV!L:L,"AMITAV TARAFDER",CONV!R:R,"Elect"),COUNTIFS(RHA!C:C,"LPG",RHA!L:L,"AMITAV TARAFDER")) -> 6 | U29: =SUM(COUNTIFS(North!C:C,"LPS",North!L:L,"AMITAV TARAFDER"),COUNTIFS(KOAA!C:C,"LPS",KOAA!L:L,"AMITAV TARAFDER"),COUNTIFS(South!C:C,"LPS",South!L:L,"AMITAV TARAFDER"),COUNTIFS(DDJ!C:C,"LPS",DDJ!L:L,"AMITAV TARAFDER"),COUNTIFS(BT!C:C,"LPS",BT!L:L,"AMITAV TARAFDER"),COUNTIFS(NH!C:C,"LPS",NH!L:L,"AMITAV TARAFDER"),COUNTIFS(CONV!C:C,"LPS",CONV!L:L,"AMITAV TARAFDER",CONV!R:R,"Elect")) -> 5 | V29: =SUM(COUNTIFS(North!C:C,"ALP",North!L:L,"AMITAV TARAFDER"),COUNTIFS(KOAA!C:C,"ALP",KOAA!L:L,"AMITAV TARAFDER"),COUNTIFS(South!C:C,"ALP",South!L:L,"AMITAV TARAFDER"),COUNTIFS(DDJ!C:C,"ALP",DDJ!L:L,"AMITAV TARAFDER"),COUNTIFS(BT!C:C,"ALP",BT!L:L,"AMITAV TARAFDER"),COUNTIFS(NH!C:C,"ALP",NH!L:L,"AMITAV TARAFDER"),COUNTIFS(CONV!C:C,"ALP",CONV!L:L,"AMITAV TARAFDER"),COUNTIFS(RHA!C:C,"ALP",RHA!L:L,"AMITAV TARAFDER")) -> 17 | W29: =IFERROR(__xludf.DUMMYFUNCTION("IMPORTRANGE(""https://docs.google.com/spreadsheets/d/1mJewmOL7uFLOZntlUxVr1CaPuLkVrP0Vw3DUi9u3slk/edit?usp=sharing"",""SUMMARY!C2"")"),0) -> 0 | X29: =SUM(Q29:W29) -> 64 | Y29: =SUM(Q29:T29) -> 42
A30: Motorman | B30: =COUNTIFS(CONV!C:C,"MOTORMAN",CONV!K:K,"CC(R) NORTH",CONV!R:R,"DSL") -> 0 | C30: =COUNTIFS(CONV!C:C,"motorman",CONV!K:K,"CC(R) South",CONV!R:R,"DSL") -> 0 | D30: =COUNTIFS(CONV!C:C,"MOTORMAN",CONV!K:K,"CC(R) KOAA",CONV!R:R,"DSL") -> 0 | E30: =COUNTIFS(CONV!C:C,"MOTORMAN",CONV!K:K,"CC(R) DDJ",CONV!R:R,"DSL") -> 0 | F30: =COUNTIFS(CONV!C:C,"MOTORMAN",CONV!K:K,"CC(R) NH",CONV!R:R,"DSL") -> 0 | G30: =COUNTIFS(CONV!C:C,"MOTORMAN",CONV!K:K,"CC(R) BT",CONV!R:R,"DSL") -> 0 | H30: =COUNTIFS(CONV!C:C,"MOTORMAN",CONV!K:K,"CC(R) RHA",CONV!R:R,"DSL") -> 0 | I30: =SUM(B30:H30) -> 0 | O30: 2 | P30: SWAPAN KUMAR MONDAL | Q30: =SUM(COUNTIFS(North!C:C,"LPM",North!L:L,"SWAPAN KUMAR MONDAL"),COUNTIFS(KOAA!C:C,"LPM",KOAA!L:L,"SWAPAN KUMAR MONDAL"),COUNTIFS(South!C:C,"LPM",South!L:L,"SWAPAN KUMAR MONDAL"),COUNTIFS(DDJ!C:C,"LPM",DDJ!L:L,"SWAPAN KUMAR MONDAL"),COUNTIFS(BT!C:C,"LPM",BT!L:L,"SWAPAN KUMAR MONDAL"),COUNTIFS(NH!C:C,"LPM",NH!L:L,"SWAPAN KUMAR MONDAL"),COUNTIFS(CONV!C:C,"LPM",CONV!L:L,"SWAPAN KUMAR MONDAL")) -> 0 | R30: =SUM(COUNTIFS(North!C:C,"LPP(LOCO)",North!L:L,"SWAPAN KUMAR MONDAL"),COUNTIFS(KOAA!C:C,"LPP(LOCO)",KOAA!L:L,"SWAPAN KUMAR MONDAL"),COUNTIFS(South!C:C,"LPP(LOCO)",South!L:L,"SWAPAN KUMAR MONDAL"),COUNTIFS(DDJ!C:C,"LPP(LOCO)",DDJ!L:L,"SWAPAN KUMAR MONDAL"),COUNTIFS(BT!C:C,"LPP(LOCO)",BT!L:L,"SWAPAN KUMAR MONDAL"),COUNTIFS(NH!C:C,"LPP(LOCO)",NH!L:L,"SWAPAN KUMAR MONDAL"),COUNTIFS(CONV!C:C,"LPP(LOCO)",CONV!L:L,"SWAPAN KUMAR MONDAL")) -> 0 | S30: =SUM(COUNTIFS(North!C:C,"Motorman",North!L:L,"SWAPAN KUMAR MONDAL"),COUNTIFS(KOAA!C:C,"Motorman",KOAA!L:L,"SWAPAN KUMAR MONDAL"),COUNTIFS(South!C:C,"Motorman",South!L:L,"SWAPAN KUMAR MONDAL"),COUNTIFS(DDJ!C:C,"Motorman",DDJ!L:L,"SWAPAN KUMAR MONDAL"),COUNTIFS(BT!C:C,"Motorman",BT!L:L,"SWAPAN KUMAR MONDAL"),COUNTIFS(NH!C:C,"Motorman",NH!L:L,"SWAPAN KUMAR MONDAL"),COUNTIFS(CONV!C:C,"MOTORMAN",CONV!L:L,"SWAPAN KUMAR MONDAL"),COUNTIFS(RHA!C:C,"MOTORMAN",RHA!L:L,"SWAPAN KUMAR MONDAL")) -> 36 | T30: =SUM(COUNTIFS(North!C:C,"LPG",North!L:L,"SWAPAN KUMAR MONDAL"),COUNTIFS(KOAA!C:C,"LPG",KOAA!L:L,"SWAPAN KUMAR MONDAL"),COUNTIFS(South!C:C,"LPG",South!L:L,"SWAPAN KUMAR MONDAL"),COUNTIFS(DDJ!C:C,"LPG",DDJ!L:L,"SWAPAN KUMAR MONDAL"),COUNTIFS(BT!C:C,"LPG",BT!L:L,"SWAPAN KUMAR MONDAL"),COUNTIFS(NH!C:C,"LPG",NH!L:L,"SWAPAN KUMAR MONDAL"),COUNTIFS(CONV!C:C,"LPG",CONV!L:L,"SWAPAN KUMAR MONDAL",CONV!R:R,"Elect"),,COUNTIFS(RHA!C:C,"LPG",RHA!L:L,"SWAPAN KUMAR MONDAL")) -> 9 | U30: =SUM(COUNTIFS(North!C:C,"LPS",North!L:L,"SWAPAN KUMAR MONDAL"),COUNTIFS(KOAA!C:C,"LPS",KOAA!L:L,"SWAPAN KUMAR MONDAL"),COUNTIFS(South!C:C,"LPS",South!L:L,"SWAPAN KUMAR MONDAL"),COUNTIFS(DDJ!C:C,"LPS",DDJ!L:L,"SWAPAN KUMAR MONDAL"),COUNTIFS(BT!C:C,"LPS",BT!L:L,"SWAPAN KUMAR MONDAL"),COUNTIFS(NH!C:C,"LPS",NH!L:L,"SWAPAN KUMAR MONDAL"),COUNTIFS(CONV!C:C,"LPS",CONV!L:L,"SWAPAN KUMAR MONDAL",CONV!R:R,"Elect"),COUNTIFS(RHA!C:C,"LPS",RHA!L:L,"SWAPAN KUMAR MONDAL")) -> 6 | V30: =SUM(COUNTIFS(North!C:C,"ALP",North!L:L,"SWAPAN KUMAR MONDAL"),COUNTIFS(KOAA!C:C,"ALP",KOAA!L:L,"SWAPAN KUMAR MONDAL"),COUNTIFS(South!C:C,"ALP",South!L:L,"SWAPAN KUMAR MONDAL"),COUNTIFS(DDJ!C:C,"ALP",DDJ!L:L,"SWAPAN KUMAR MONDAL"),COUNTIFS(BT!C:C,"ALP",BT!L:L,"SWAPAN KUMAR MONDAL"),COUNTIFS(NH!C:C,"ALP",NH!L:L,"SWAPAN KUMAR MONDAL"),COUNTIFS(CONV!C:C,"ALP",CONV!L:L,"SWAPAN KUMAR MONDAL"),COUNTIFS(RHA!C:C,"ALP",RHA!L:L,"SWAPAN KUMAR MONDAL")) -> 14 | W30: 0 | X30: =SUM(Q30:W30) -> 65 | Y30: =SUM(Q30:T30) -> 45
A31: LPP(Loco) | B31: =COUNTIFS(CONV!C:C,"LPP(LOCO)",CONV!K:K,"CC(R) NORTH",CONV!R:R,"DSL") -> 0 | C31: =COUNTIFS(CONV!C:C,"LPP(loco)",CONV!K:K,"CC(R) South",CONV!R:R,"DSL") -> 0 | D31: =COUNTIFS(CONV!C:C,"LPP(LOCO)",CONV!K:K,"CC(R) KOAA",CONV!R:R,"DSL") -> 0 | E31: =COUNTIFS(CONV!C:C,"LPP(LOCO)",CONV!K:K,"CC(R) DDJ",CONV!R:R,"DSL") -> 0 | F31: =COUNTIFS(CONV!C:C,"LPP(LOCO)",CONV!K:K,"CC(R) NH",CONV!R:R,"DSL") -> 0 | G31: =COUNTIFS(CONV!C:C,"LPP(LOCO)",CONV!K:K,"CC(R) BT",CONV!R:R,"DSL") -> 0 | H31: =COUNTIFS(CONV!C:C,"LPP(LOCO)",CONV!K:K,"CC(R) RHA",CONV!R:R,"DSL") -> 0 | I31: =SUM(B31:H31) -> 0 | O31: 3 | P31: Ruwel Murmu | Q31: =SUM(COUNTIFS(North!C:C,"LPM",North!L:L,"Ruwel Murmu"),COUNTIFS(KOAA!C:C,"LPM",KOAA!L:L,"ruwel murmu"),COUNTIFS(South!C:C,"LPM",South!L:L,"ruwel murmu"),COUNTIFS(DDJ!C:C,"LPM",DDJ!L:L,"ruwel murmu"),COUNTIFS(BT!C:C,"LPM",BT!L:L,"ruwel murmu"),COUNTIFS(NH!C:C,"LPM",NH!L:L,"ruwel murmu"),COUNTIFS(CONV!C:C,"LPM",CONV!L:L,"RUWEL MURMU")) -> 14 | R31: =SUM(COUNTIFS(North!C:C,"LPP(LOCO)",North!L:L,"Ruwel Murmu"),COUNTIFS(KOAA!C:C,"LPP(LOCO)",KOAA!L:L,"ruwel murmu"),COUNTIFS(South!C:C,"LPP(LOCO)",South!L:L,"ruwel murmu"),COUNTIFS(DDJ!C:C,"LPP(LOCO)",DDJ!L:L,"ruwel murmu"),COUNTIFS(BT!C:C,"LPP(LOCO)",BT!L:L,"ruwel murmu"),COUNTIFS(NH!C:C,"LPP(LOCO)",NH!L:L,"ruwel murmu"),COUNTIFS(CONV!C:C,"LPP(LOCO)",CONV!L:L,"RUWEL MURMU")) -> 0 | S31: =SUM(COUNTIFS(North!C:C,"MOTORMAN",North!L:L,"Ruwel Murmu"),COUNTIFS(KOAA!C:C,"MOTORMAN",KOAA!L:L,"ruwel murmu"),COUNTIFS(South!C:C,"MOTORMAN",South!L:L,"ruwel murmu"),COUNTIFS(DDJ!C:C,"MOTORMAN",DDJ!L:L,"ruwel murmu"),COUNTIFS(BT!C:C,"MOTORMAN",BT!L:L,"ruwel murmu"),COUNTIFS(NH!C:C,"MOTORMAN",NH!L:L,"ruwel murmu"),COUNTIFS(CONV!C:C,"MOTORMAN",CONV!L:L,"RUWEL MURMU"),COUNTIFS(RHA!C:C,"MOTORMAN",RHA!L:L,"ruwel murmu")) -> 9 | T31: =SUM(COUNTIFS(North!C:C,"LPG",North!L:L,"Ruwel Murmu"),COUNTIFS(KOAA!C:C,"LPG",KOAA!L:L,"ruwel murmu"),COUNTIFS(South!C:C,"LPG",South!L:L,"ruwel murmu"),COUNTIFS(DDJ!C:C,"LPG",DDJ!L:L,"ruwel murmu"),COUNTIFS(BT!C:C,"LPG",BT!L:L,"ruwel murmu"),COUNTIFS(NH!C:C,"LPG",NH!L:L,"ruwel murmu"),COUNTIFS(CONV!C:C,"LPG",CONV!L:L,"RUWEL MURMU",CONV!R:R,"Elect"),COUNTIFS(RHA!C:C,"LPG",RHA!L:L,"RUWEL MURMU")) -> 4 | U31: =SUM(COUNTIFS(North!C:C,"LPS",North!L:L,"Ruwel Murmu"),COUNTIFS(KOAA!C:C,"LPS",KOAA!L:L,"ruwel murmu"),COUNTIFS(South!C:C,"LPS",South!L:L,"ruwel murmu"),COUNTIFS(DDJ!C:C,"LPS",DDJ!L:L,"ruwel murmu"),COUNTIFS(BT!C:C,"LPS",BT!L:L,"ruwel murmu"),COUNTIFS(NH!C:C,"LPS",NH!L:L,"ruwel murmu"),COUNTIFS(CONV!C:C,"LPS",CONV!L:L,"RUWEL MURMU",CONV!R:R,"Elect"),COUNTIFS(RHA!C:C,"LPS",RHA!L:L,"RUWEL MURMU")) -> 1 | V31: =SUM(COUNTIFS(North!C:C,"ALP",North!L:L,"Ruwel Murmu"),COUNTIFS(KOAA!C:C,"ALP",KOAA!L:L,"ruwel murmu"),COUNTIFS(South!C:C,"ALP",South!L:L,"ruwel murmu"),COUNTIFS(DDJ!C:C,"ALP",DDJ!L:L,"ruwel murmu"),COUNTIFS(BT!C:C,"ALP",BT!L:L,"ruwel murmu"),COUNTIFS(NH!C:C,"ALP",NH!L:L,"ruwel murmu"),COUNTIFS(CONV!C:C,"ALP",CONV!L:L,"RUWEL MURMU"),COUNTIFS(RHA!C:C,"ALP",RHA!L:L,"RUWEL MURMU")) -> 17 | W31: 0 | X31: =SUM(Q31:W31) -> 45 | Y31: =SUM(Q31:T31) -> 27
A32: LPG | B32: =COUNTIFS(CONV!C:C,"LPG",CONV!K:K,"CC(R) NORTH",CONV!R:R,"DSL") -> 0 | C32: =COUNTIFS(CONV!C:C,"LPG",CONV!K:K,"CC(R) South",CONV!R:R,"DSL") -> 0 | D32: =COUNTIFS(CONV!C:C,"LPG",CONV!K:K,"CC(R) KOAA",CONV!R:R,"DSL") -> 0 | E32: =COUNTIFS(CONV!C:C,"LPG",CONV!K:K,"CC(R) DDJ",CONV!R:R,"DSL") -> 77 | F32: =COUNTIFS(CONV!C:C,"LPG",CONV!K:K,"CC(R) NH",CONV!R:R,"DSL") -> 21 | G32: =COUNTIFS(CONV!C:C,"LPG",CONV!K:K,"CC(R) BT",CONV!R:R,"DSL") -> 0 | H32: =COUNTIFS(CONV!C:C,"LPG",CONV!K:K,"CC(R) RHA",CONV!R:R,"DSL") -> 13 | I32: =SUM(B32:H32) -> 111 | O32: 4 | P32: Rajeev Kumar Sabherwal | Q32: =SUM(COUNTIFS(North!C:C,"LPM",North!L:L,"R K Sabherwal"),COUNTIFS(KOAA!C:C,"LPM",KOAA!L:L,"R K Sabherwal"),COUNTIFS(South!C:C,"LPM",South!L:L,"R K Sabherwal"),COUNTIFS(DDJ!C:C,"LPM",DDJ!L:L,"R K Sabherwal"),COUNTIFS(BT!C:C,"LPM",BT!L:L,"R K Sabherwal"),COUNTIFS(NH!C:C,"LPM",NH!L:L,"R K Sabherwal"),COUNTIFS(CONV!C:C,"LPM",CONV!L:L,"R K SABHERWAL")) -> 15 | R32: =SUM(COUNTIFS(North!C:C,"LPp(loco)",North!L:L,"R K Sabherwal"),COUNTIFS(KOAA!C:C,"LPp(loco)",KOAA!L:L,"R K Sabherwal"),COUNTIFS(South!C:C,"LPp(loco)",South!L:L,"R K Sabherwal"),COUNTIFS(DDJ!C:C,"LPp(loco)",DDJ!L:L,"R K Sabherwal"),COUNTIFS(BT!C:C,"LPp(loco)",BT!L:L,"R K Sabherwal"),COUNTIFS(NH!C:C,"LPp(loco)",NH!L:L,"R K Sabherwal"),COUNTIFS(CONV!C:C,"LPP(LOCO)",CONV!L:L,"R K SABHERWAL")) -> 0 | S32: =SUM(COUNTIFS(North!C:C,"motorman",North!L:L,"R K Sabherwal"),COUNTIFS(KOAA!C:C,"motorman",KOAA!L:L,"R K Sabherwal"),COUNTIFS(South!C:C,"motorman",South!L:L,"R K Sabherwal"),COUNTIFS(DDJ!C:C,"motorman",DDJ!L:L,"R K Sabherwal"),COUNTIFS(BT!C:C,"motorman",BT!L:L,"R K Sabherwal"),COUNTIFS(NH!C:C,"motorman",NH!L:L,"R K Sabherwal"),COUNTIFS(CONV!C:C,"MOTORMAN",CONV!L:L,"R K SABHERWAL"),COUNTIFS(RHA!C:C,"MOTORMAN",RHA!L:L,"R K SABHERWAL")) -> 11 | T32: =SUM(COUNTIFS(North!C:C,"lpg",North!L:L,"R K Sabherwal"),COUNTIFS(KOAA!C:C,"lpg",KOAA!L:L,"R K Sabherwal"),COUNTIFS(South!C:C,"lpg",South!L:L,"R K Sabherwal"),COUNTIFS(DDJ!C:C,"lpg",DDJ!L:L,"R K Sabherwal"),COUNTIFS(BT!C:C,"lpg",BT!L:L,"R K Sabherwal"),COUNTIFS(NH!C:C,"lpg",NH!L:L,"R K Sabherwal"),COUNTIFS(CONV!C:C,"LPG",CONV!L:L,"R K SABHERWAL",CONV!R:R,"Elect"),COUNTIFS(RHA!C:C,"LPG",RHA!L:L,"R K SABHERWAL")) -> 4 | U32: =SUM(COUNTIFS(North!C:C,"lps",North!L:L,"R K Sabherwal"),COUNTIFS(KOAA!C:C,"lps",KOAA!L:L,"R K Sabherwal"),COUNTIFS(South!C:C,"lps",South!L:L,"R K Sabherwal"),COUNTIFS(DDJ!C:C,"lps",DDJ!L:L,"R K Sabherwal"),COUNTIFS(BT!C:C,"lps",BT!L:L,"R K Sabherwal"),COUNTIFS(NH!C:C,"lps",NH!L:L,"R K Sabherwal"),COUNTIFS(CONV!C:C,"LPS",CONV!L:L,"R K SABHERWAL",CONV!R:R,"Elect"),COUNTIFS(RHA!C:C,"LPS",RHA!L:L,"R K SABHERWAL")) -> 5 | V32: =SUM(COUNTIFS(North!C:C,"alp",North!L:L,"R K Sabherwal"),COUNTIFS(KOAA!C:C,"alp",KOAA!L:L,"R K Sabherwal"),COUNTIFS(South!C:C,"alp",South!L:L,"R K Sabherwal"),COUNTIFS(DDJ!C:C,"alp",DDJ!L:L,"R K Sabherwal"),COUNTIFS(BT!C:C,"alp",BT!L:L,"R K Sabherwal"),COUNTIFS(NH!C:C,"alp",NH!L:L,"R K Sabherwal"),COUNTIFS(CONV!C:C,"ALP",CONV!L:L,"R K SABHERWAL"),COUNTIFS(RHA!C:C,"ALP",RHA!L:L,"R K SABHERWAL")) -> 12 | W32: 0 | X32: =SUM(Q32:W32) -> 47 | Y32: =SUM(Q32:T32) -> 30
A33: LPS | B33: =COUNTIFS(CONV!C:C,"LPS",CONV!K:K,"CC(R) NORTH",CONV!R:R,"DSL") -> 0 | C33: =COUNTIFS(CONV!C:C,"LPS",CONV!K:K,"CC(R) South",CONV!R:R,"DSL") -> 0 | D33: =COUNTIFS(CONV!C:C,"LPS",CONV!K:K,"CC(R) KOAA",CONV!R:R,"DSL") -> 2 | E33: =COUNTIFS(CONV!C:C,"LPS",CONV!K:K,"CC(R) DDJ",CONV!R:R,"DSL") -> 5 | F33: =COUNTIFS(CONV!C:C,"LPS",CONV!K:K,"CC(R) NH",CONV!R:R,"DSL") -> 6 | G33: =COUNTIFS(CONV!C:C,"LPS",CONV!K:K,"CC(R) BT",CONV!R:R,"DSL") -> 0 | H33: =COUNTIFS(CONV!C:C,"LPS",CONV!K:K,"CC(R) RHA",CONV!R:R,"DSL") -> 4 | I33: =SUM(B33:H33) -> 17 | O33: 5 | P33: Kalyan Das | Q33: =SUM(COUNTIFS(North!C:C,"LPM",North!L:L,"kalyan das"),COUNTIFS(KOAA!C:C,"LPM",KOAA!L:L,"kalyan das"),COUNTIFS(South!C:C,"LPM",South!L:L,"kalyan das"),COUNTIFS(DDJ!C:C,"LPM",DDJ!L:L,"kalyan das"),COUNTIFS(BT!C:C,"LPM",BT!L:L,"kalyan das"),COUNTIFS(NH!C:C,"LPM",NH!L:L,"kalyan das"),COUNTIFS(CONV!C:C,"LPM",CONV!L:L,"KALYAN DAS")) -> 0 | R33: =SUM(COUNTIFS(North!C:C,"LPp(loco)",North!L:L,"kalyan das"),COUNTIFS(KOAA!C:C,"LPp(loco)",KOAA!L:L,"kalyan das"),COUNTIFS(South!C:C,"LPp(loco)",South!L:L,"kalyan das"),COUNTIFS(DDJ!C:C,"LPp(loco)",DDJ!L:L,"kalyan das"),COUNTIFS(BT!C:C,"LPp(loco)",BT!L:L,"kalyan das"),COUNTIFS(NH!C:C,"LPp(loco)",NH!L:L,"kalyan das"),COUNTIFS(CONV!C:C,"LPP(LOCO)",CONV!L:L,"KALYAN DAS")) -> 0 | S33: =SUM(COUNTIFS(North!C:C,"motorman",North!L:L,"kalyan das"),COUNTIFS(KOAA!C:C,"motorman",KOAA!L:L,"kalyan das"),COUNTIFS(South!C:C,"motorman",South!L:L,"kalyan das"),COUNTIFS(DDJ!C:C,"motorman",DDJ!L:L,"kalyan das"),COUNTIFS(BT!C:C,"motorman",BT!L:L,"kalyan das"),COUNTIFS(NH!C:C,"motorman",NH!L:L,"kalyan das"),COUNTIFS(CONV!C:C,"MOTORMAN",CONV!L:L,"KALYAN DAS"),COUNTIFS(RHA!C:C,"motorman",RHA!L:L,"kalyan das")) -> 35 | T33: =SUM(COUNTIFS(North!C:C,"lpg",North!L:L,"kalyan das"),COUNTIFS(KOAA!C:C,"lpg",KOAA!L:L,"kalyan das"),COUNTIFS(South!C:C,"lpg",South!L:L,"kalyan das"),COUNTIFS(DDJ!C:C,"lpg",DDJ!L:L,"kalyan das"),COUNTIFS(BT!C:C,"lpg",BT!L:L,"kalyan das"),COUNTIFS(NH!C:C,"lpg",NH!L:L,"kalyan das"),COUNTIFS(CONV!C:C,"LPG",CONV!L:L,"KALYAN DAS",CONV!R:R,"Elect"),COUNTIFS(RHA!C:C,"LPG",RHA!L:L,"KALYAN DAS")) -> 10 | U33: =SUM(COUNTIFS(North!C:C,"lps",North!L:L,"kalyan das"),COUNTIFS(KOAA!C:C,"lps",KOAA!L:L,"kalyan das"),COUNTIFS(South!C:C,"lps",South!L:L,"kalyan das"),COUNTIFS(DDJ!C:C,"lps",DDJ!L:L,"kalyan das"),COUNTIFS(BT!C:C,"lps",BT!L:L,"kalyan das"),COUNTIFS(NH!C:C,"lps",NH!L:L,"kalyan das"),COUNTIFS(CONV!C:C,"lps",CONV!L:L,"kalyan das",CONV!R:R,"Elect"),COUNTIFS(RHA!C:C,"lps",RHA!L:L,"kalyan das")) -> 7 | V33: =SUM(COUNTIFS(North!C:C,"alp",North!L:L,"Kalyan Das"),COUNTIFS(KOAA!C:C,"alp",KOAA!L:L,"Kalyan Das"),COUNTIFS(South!C:C,"alp",South!L:L,"Kalyan Das"),COUNTIFS(DDJ!C:C,"alp",DDJ!L:L,"Kalyan Das"),COUNTIFS(BT!C:C,"alp",BT!L:L,"Kalyan Das"),COUNTIFS(NH!C:C,"alp",NH!L:L,"Kalyan Das"),COUNTIFS(CONV!C:C,"ALP",CONV!L:L,"Kalyan Das"),COUNTIFS(RHA!C:C,"ALP",RHA!L:L,"Kalyan Das")) -> 15 | W33: 0 | X33: =SUM(Q33:W33) -> 67 | Y33: =SUM(Q33:T33) -> 45
A34: ALP | B34: =COUNTIFS(CONV!C:C,"ALP",CONV!K:K,"CC(R) NORTH",CONV!R:R,"DSL") -> 0 | C34: =COUNTIFS(CONV!C:C,"ALP",CONV!K:K,"CC(R) South",CONV!R:R,"DSL") -> 0 | D34: =COUNTIFS(CONV!C:C,"ALP",CONV!K:K,"CC(R) KOAA",CONV!R:R,"DSL") -> 0 | E34: =COUNTIFS(CONV!C:C,"ALP",CONV!K:K,"CC(R) DDJ",CONV!R:R,"DSL") -> 39 | F34: =COUNTIFS(CONV!C:C,"ALP",CONV!K:K,"CC(R) NH",CONV!R:R,"DSL") -> 11 | G34: =COUNTIFS(CONV!C:C,"ALP",CONV!K:K,"CC(R) BT",CONV!R:R,"DSL") -> 0 | H34: =COUNTIFS(CONV!C:C,"ALP",CONV!K:K,"CC(R) RHA",CONV!R:R,"DSL") -> 11 | I34: =SUM(B34:H34) -> 61 | O34: 6 | P34: UTPAL HALDER | Q34: =SUM(COUNTIFS(North!C:C,"LPM",North!L:L,"UTPAL HALDER"),COUNTIFS(KOAA!C:C,"LPM",KOAA!L:L,"UTPAL HALDER"),COUNTIFS(South!C:C,"LPM",South!L:L,"UTPAL HALDER"),COUNTIFS(DDJ!C:C,"LPM",DDJ!L:L,"UTPAL HALDER"),COUNTIFS(BT!C:C,"LPM",BT!L:L,"UTPAL HALDER"),COUNTIFS(NH!C:C,"LPM",NH!L:L,"UTPAL HALDER"),COUNTIFS(CONV!C:C,"LPM",CONV!L:L,"UTPAL HALDER")) -> 0 | R34: =SUM(COUNTIFS(North!C:C,"lpp(loco)",North!L:L,"UTPAL HALDER"),COUNTIFS(KOAA!C:C,"lpp(loco)",KOAA!L:L,"UTPAL HALDER"),COUNTIFS(South!C:C,"lpp(loco)",South!L:L,"UTPAL HALDER"),COUNTIFS(DDJ!C:C,"lpp(loco)",DDJ!L:L,"UTPAL HALDER"),COUNTIFS(BT!C:C,"lpp(loco)",BT!L:L,"UTPAL HALDER"),COUNTIFS(NH!C:C,"lpp(loco)",NH!L:L,"UTPAL HALDER"),COUNTIFS(CONV!C:C,"LPP(LOCO)",CONV!L:L,"UTPAL HALDER")) -> 2 | S34: =SUM(COUNTIFS(North!C:C,"motorman",North!L:L,"UTPAL HALDER"),COUNTIFS(KOAA!C:C,"motorman",KOAA!L:L,"UTPAL HALDER"),COUNTIFS(South!C:C,"motorman",South!L:L,"UTPAL HALDER"),COUNTIFS(DDJ!C:C,"motorman",DDJ!L:L,"UTPAL HALDER"),COUNTIFS(BT!C:C,"motorman",BT!L:L,"UTPAL HALDER"),COUNTIFS(NH!C:C,"motorman",NH!L:L,"UTPAL HALDER"),COUNTIFS(CONV!C:C,"MOTORMAN",CONV!L:L,"UTPAL HALDER"),COUNTIFS(RHA!C:C,"motorman",RHA!L:L,"UTPAL HALDER")) -> 7 | T34: =SUM(COUNTIFS(North!C:C,"lpg",North!L:L,"UTPAL HALDER"),COUNTIFS(KOAA!C:C,"lpg",KOAA!L:L,"UTPAL HALDER"),COUNTIFS(South!C:C,"lpg",South!L:L,"UTPAL HALDER"),COUNTIFS(DDJ!C:C,"lpg",DDJ!L:L,"UTPAL HALDER"),COUNTIFS(BT!C:C,"lpg",BT!L:L,"sibasis roy"),COUNTIFS(NH!C:C,"lpg",NH!L:L,"UTPAL HALDER"),COUNTIFS(CONV!C:C,"LPG",CONV!L:L,"UTPAL HALDER",CONV!R:R,"Elect"),COUNTIFS(RHA!C:C,"LPG",RHA!L:L,"UTPAL HALDER")) -> 2 | U34: =SUM(COUNTIFS(North!C:C,"lps",North!L:L,"UTPAL HALDER"),COUNTIFS(KOAA!C:C,"lps",KOAA!L:L,"UTPAL HALDER"),COUNTIFS(South!C:C,"lps",South!L:L,"UTPAL HALDER"),COUNTIFS(DDJ!C:C,"lps",DDJ!L:L,"UTPAL HALDER"),COUNTIFS(BT!C:C,"lps",BT!L:L,"UTPAL HALDER"),COUNTIFS(NH!C:C,"lps",NH!L:L,"UTPAL HALDER"),COUNTIFS(CONV!C:C,"LPS",CONV!L:L,"UTPAL HALDER",CONV!R:R,"Elect"),COUNTIFS(CONV!C:C,"ALP",CONV!L:L,"UTPAL HALDER",CONV!R:R,"Elect"),COUNTIFS(RHA!C:C,"ALP",RHA!L:L,"UTPAL HALDER")) -> 1 | V34: =SUM(COUNTIFS(North!C:C,"alp",North!L:L,"UTPAL HALDER"),COUNTIFS(KOAA!C:C,"alp",KOAA!L:L,"UTPAL HALDER"),COUNTIFS(South!C:C,"alp",South!L:L,"UTPAL HALDER"),COUNTIFS(DDJ!C:C,"alp",DDJ!L:L,"UTPAL HALDER"),COUNTIFS(BT!C:C,"alp",BT!L:L,"sibasis roy"),COUNTIFS(NH!C:C,"alp",NH!L:L,"UTPAL HALDER"),COUNTIFS(RHA!C:C,"alp",RHA!L:L,"UTPAL HALDER")) -> 1 | W34: 0 | X34: =SUM(Q34:W34) -> 13 | Y34: =SUM(Q34:T34) -> 11
A35: Total | B35: =SUM(B29:B34) -> 0 | C35: =SUM(C29:C34) -> 0 | D35: =SUM(D29:D34) -> 2 | E35: =SUM(E29:E34) -> 121 | F35: =SUM(F29:F34) -> 38 | G35: =SUM(G29:G34) -> 0 | H35: =SUM(H29:H34) -> 28 | I35: =SUM(B35:H35) -> 189 | O35: 7 | P35: S S Munda | Q35: =SUM(COUNTIFS(North!C:C,"lpm",North!L:L,"S S MUNDA"),COUNTIFS(KOAA!C:C,"lpm",KOAA!L:L,"S S MUNDA"),COUNTIFS(South!C:C,"lpm",South!L:L,"S S MUNDA"),COUNTIFS(DDJ!C:C,"lpm",DDJ!L:L,"S S MUNDA"),COUNTIFS(BT!C:C,"lpm",BT!L:L,"S S MUNDA"),COUNTIFS(NH!C:C,"lpm",NH!L:L,"S S MUNDA"),COUNTIFS(CONV!C:C,"LPM",CONV!L:L,"S S MUNDA")) -> 1 | R35: =SUM(COUNTIFS(North!C:C,"LPP(LOCO)",North!L:L,"S S MUNDA"),COUNTIFS(KOAA!C:C,"LPP(LOCO)",KOAA!L:L,"S S MUNDA"),COUNTIFS(South!C:C,"LPP(LOCO)",South!L:L,"S S MUNDA"),COUNTIFS(DDJ!C:C,"LPP(LOCO)",DDJ!L:L,"S S MUNDA"),COUNTIFS(BT!C:C,"LPP(LOCO)",BT!L:L,"S S MUNDA"),COUNTIFS(NH!C:C,"LPP(LOCO)",NH!L:L,"S S MUNDA"),COUNTIFS(CONV!C:C,"LPP(LOCO)",CONV!L:L,"S S MUNDA")) -> 0 | S35: =SUM(COUNTIFS(North!C:C,"MOTORMAN",North!L:L,"S S MUNDA"),COUNTIFS(KOAA!C:C,"MOTORMAN",KOAA!L:L,"S S MUNDA"),COUNTIFS(South!C:C,"MOTORMAN",South!L:L,"S S MUNDA"),COUNTIFS(DDJ!C:C,"MOTORMAN",DDJ!L:L,"S S MUNDA"),COUNTIFS(BT!C:C,"MOTORMAN",BT!L:L,"S S MUNDA"),COUNTIFS(NH!C:C,"MOTORMAN",NH!L:L,"S S MUNDA"),COUNTIFS(CONV!C:C,"MOTORMAN",CONV!L:L,"S S MUNDA"),COUNTIFS(RHA!C:C,"MOTORMAN",RHA!L:L,"S S MUNDA")) -> 15 | T35: =SUM(COUNTIFS(North!C:C,"LPG",North!L:L,"S S MUNDA"),COUNTIFS(KOAA!C:C,"LPG",KOAA!L:L,"S S MUNDA"),COUNTIFS(South!C:C,"LPG",South!L:L,"S S MUNDA"),COUNTIFS(DDJ!C:C,"LPG",DDJ!L:L,"S S MUNDA"),COUNTIFS(BT!C:C,"LPG",BT!L:L,"S S MUNDA"),COUNTIFS(NH!C:C,"LPG",NH!L:L,"S S MUNDA"),COUNTIFS(CONV!C:C,"LPG",CONV!L:L,"S S MUNDA",CONV!R:R,"Elect"),COUNTIFS(RHA!C:C,"LPG",RHA!L:L,"S S MUNDA")) -> 5 | U35: =SUM(COUNTIFS(North!C:C,"LPS",North!L:L,"S S MUNDA"),COUNTIFS(KOAA!C:C,"LPS",KOAA!L:L,"S S MUNDA"),COUNTIFS(South!C:C,"LPS",South!L:L,"S S MUNDA"),COUNTIFS(DDJ!C:C,"LPS",DDJ!L:L,"S S MUNDA"),COUNTIFS(BT!C:C,"LPS",BT!L:L,"S S MUNDA"),COUNTIFS(NH!C:C,"LPS",NH!L:L,"S S MUNDA"),COUNTIFS(CONV!C:C,"LPS",CONV!L:L,"S S MUNDA",CONV!R:R,"Elect"),COUNTIFS(RHA!C:C,"LPS",RHA!L:L,"S S MUNDA")) -> 1 | V35: =SUM(COUNTIFS(North!C:C,"ALP",North!L:L,"S S MUNDA"),COUNTIFS(KOAA!C:C,"ALP",KOAA!L:L,"S S MUNDA"),COUNTIFS(South!C:C,"ALP",South!L:L,"S S MUNDA"),COUNTIFS(DDJ!C:C,"ALP",DDJ!L:L,"S S MUNDA"),COUNTIFS(BT!C:C,"ALP",BT!L:L,"S S MUNDA"),COUNTIFS(NH!C:C,"ALP",NH!L:L,"S S MUNDA"),COUNTIFS(CONV!C:C,"ALP",CONV!L:L,"S S MUNDA"),COUNTIFS(RHA!C:C,"ALP",RHA!L:L,"S S MUNDA")) -> 8 | W35: =IFERROR(__xludf.DUMMYFUNCTION("IMPORTRANGE(""https://docs.google.com/spreadsheets/d/1mJewmOL7uFLOZntlUxVr1CaPuLkVrP0Vw3DUi9u3slk/edit?usp=sharing"",""SUMMARY!C34"")"),42) -> 42 | X35: =SUM(Q35:W35) -> 72 | Y35: =SUM(Q35:T35) -> 21
O36: 8 | P36: SANJAY KR GUPTA | Q36: =SUM(COUNTIFS(North!C:C,"lpm",North!L:L,"SANJAY KR GUPTA"),COUNTIFS(KOAA!C:C,"lpm",KOAA!L:L,"SANJAY KR GUPTA"),COUNTIFS(South!C:C,"lpm",South!L:L,"SANJAY KR GUPTA"),COUNTIFS(DDJ!C:C,"lpm",DDJ!L:L,"SANJAY KR GUPTA"),COUNTIFS(BT!C:C,"lpm",BT!L:L,"SANJAY KR GUPTA"),COUNTIFS(NH!C:C,"lpm",NH!L:L,"SANJAY KR GUPTA"),COUNTIFS(CONV!C:C,"LPM",CONV!L:L,"SANJAY KR GUPTA")) -> 11 | R36: =SUM(COUNTIFS(North!C:C,"lpp(loco)",North!L:L,"SANJAY KR GUPTA"),COUNTIFS(KOAA!C:C,"lpp(loco)",KOAA!L:L,"SANJAY KR GUPTA"),COUNTIFS(South!C:C,"lpp(loco)",South!L:L,"SANJAY KR GUPTA"),COUNTIFS(DDJ!C:C,"lpp(loco)",DDJ!L:L,"SANJAY KR GUPTA"),COUNTIFS(BT!C:C,"lpp(loco)",BT!L:L,"SANJAY KR GUPTA"),COUNTIFS(NH!C:C,"lpp(loco)",NH!L:L,"SANJAY KR GUPTA"),COUNTIFS(CONV!C:C,"LPP(LOCO)",CONV!L:L,"SANJAY KR GUPTA")) -> 7 | S36: =SUM(COUNTIFS(North!C:C,"motorman",North!L:L,"SANJAY KR GUPTA"),COUNTIFS(KOAA!C:C,"motorman",KOAA!L:L,"SANJAY KR GUPTA"),COUNTIFS(South!C:C,"motorman",South!L:L,"SANJAY KR GUPTA"),COUNTIFS(DDJ!C:C,"motorman",DDJ!L:L,"SANJAY KR GUPTA"),COUNTIFS(BT!C:C,"motorman",BT!L:L,"SANJAY KR GUPTA"),COUNTIFS(NH!C:C,"motorman",NH!L:L,"SANJAY KR GUPTA"),COUNTIFS(CONV!C:C,"MOTORMAN",CONV!L:L,"SANJAY KR GUPTA"),COUNTIFS(RHA!C:C,"MOTORMAN",RHA!L:L,"SANJAY KR GUPTA")) -> 0 | T36: =SUM(COUNTIFS(North!C:C,"lpg",North!L:L,"SANJAY KR GUPTA"),COUNTIFS(KOAA!C:C,"lpg",KOAA!L:L,"SANJAY KR GUPTA"),COUNTIFS(South!C:C,"lpg",South!L:L,"SANJAY KR GUPTA"),COUNTIFS(DDJ!C:C,"lpg",DDJ!L:L,"SANJAY KR GUPTA"),COUNTIFS(BT!C:C,"lpg",BT!L:L,"SANJAY KR GUPTA"),COUNTIFS(NH!C:C,"lpg",NH!L:L,"SANJAY KR GUPTA"),COUNTIFS(CONV!C:C,"LPG",CONV!L:L,"SANJAY KR GUPTA",CONV!R:R,"Elect"),,COUNTIFS(RHA!C:C,"LPG",RHA!L:L,"SANJAY KR GUPTA")) -> 1 | U36: =SUM(COUNTIFS(North!C:C,"lps",North!L:L,"SANJAY KR GUPTA"),COUNTIFS(KOAA!C:C,"lps",KOAA!L:L,"SANJAY KR GUPTA"),COUNTIFS(South!C:C,"lps",South!L:L,"SANJAY KR GUPTA"),COUNTIFS(DDJ!C:C,"lps",DDJ!L:L,"SANJAY KR GUPTA"),COUNTIFS(BT!C:C,"lps",BT!L:L,"SANJAY KR GUPTA"),COUNTIFS(NH!C:C,"lps",NH!L:L,"SANJAY KR GUPTA"),COUNTIFS(CONV!C:C,"LPS",CONV!L:L,"SANJAY KR GUPTA",CONV!R:R,"Elect"),COUNTIFS(RHA!C:C,"LPS",RHA!L:L,"SANJAY KR GUPTA")) -> 13 | V36: =SUM(COUNTIFS(North!C:C,"alp",North!L:L,"SANJAY KR GUPTA"),COUNTIFS(KOAA!C:C,"alp",KOAA!L:L,"SANJAY KR GUPTA"),COUNTIFS(South!C:C,"alp",South!L:L,"SANJAY KR GUPTA"),COUNTIFS(DDJ!C:C,"alp",DDJ!L:L,"SANJAY KR GUPTA"),COUNTIFS(BT!C:C,"alp",BT!L:L,"SANJAY KR GUPTA"),COUNTIFS(NH!C:C,"alp",NH!L:L,"SANJAY KR GUPTA"),COUNTIFS(CONV!C:C,"ALP",CONV!L:L,"SANJAY KR GUPTA"),COUNTIFS(RHA!C:C,"alp",RHA!L:L,"SANJAY KR GUPTA")) -> 35 | W36: 0 | X36: =SUM(Q36:W36) -> 67 | Y36: =SUM(Q36:T36) -> 19
A37: RETIREMENT | B37: ELECT | C37: 51226 | O37: 9 | P37: SIDDHARTHA BISWAS | Q37: =SUM(COUNTIFS(North!C:C,"lpm",North!L:L,"SIDDHARTHA BISWAS"),COUNTIFS(KOAA!C:C,"lpm",KOAA!L:L,"SIDDHARTHA BISWAS"),COUNTIFS(South!C:C,"lpm",South!L:L,"SIDDHARTHA BISWAS"),COUNTIFS(DDJ!C:C,"lpm",DDJ!L:L,"SIDDHARTHA BISWAS"),COUNTIFS(BT!C:C,"lpm",BT!L:L,"SIDDHARTHA BISWAS"),COUNTIFS(NH!C:C,"lpm",NH!L:L,"SIDDHARTHA BISWAS"),COUNTIFS(CONV!C:C,"LPM",CONV!L:L,"SIDDHARTHA BISWAS")) -> 0 | R37: =SUM(COUNTIFS(North!C:C,"lpp(loco)",North!L:L,"SIDDHARTHA BISWAS"),COUNTIFS(KOAA!C:C,"lpp(loco)",KOAA!L:L,"SIDDHARTHA BISWAS"),COUNTIFS(South!C:C,"lpp(loco)",South!L:L,"SIDDHARTHA BISWAS"),COUNTIFS(DDJ!C:C,"lpp(loco)",DDJ!L:L,"SIDDHARTHA BISWAS"),COUNTIFS(BT!C:C,"lpp(loco)",BT!L:L,"SIDDHARTHA BISWAS"),COUNTIFS(NH!C:C,"lpp(loco)",NH!L:L,"SIDDHARTHA BISWAS"),COUNTIFS(CONV!C:C,"LPP(LOCO)",CONV!L:L,"SIDDHARTHA BISWAS")) -> 0 | S37: =SUM(COUNTIFS(North!C:C,"motorman",North!L:L,"SIDDHARTHA BISWAS"),COUNTIFS(KOAA!C:C,"motorman",KOAA!L:L,"SIDDHARTHA BISWAS"),COUNTIFS(South!C:C,"motorman",South!L:L,"SIDDHARTHA BISWAS"),COUNTIFS(DDJ!C:C,"motorman",DDJ!L:L,"SIDDHARTHA BISWAS"),COUNTIFS(BT!C:C,"motorman",BT!L:L,"SIDDHARTHA BISWAS"),COUNTIFS(NH!C:C,"motorman",NH!L:L,"SIDDHARTHA BISWAS"),COUNTIFS(CONV!C:C,"MOTORMAN",CONV!L:L,"SIDDHARTHA BISWAS"),COUNTIFS(RHA!C:C,"MOTORMAN",RHA!L:L,"SIDDHARTHA BISWAS")) -> 36 | T37: =SUM(COUNTIFS(North!C:C,"lpg",North!L:L,"SIDDHARTHA BISWAS"),COUNTIFS(KOAA!C:C,"lpg",KOAA!L:L,"SIDDHARTHA BISWAS"),COUNTIFS(South!C:C,"lpg",South!L:L,"SIDDHARTHA BISWAS"),COUNTIFS(DDJ!C:C,"lpg",DDJ!L:L,"SIDDHARTHA BISWAS"),COUNTIFS(BT!C:C,"lpg",BT!L:L,"SIDDHARTHA BISWAS"),COUNTIFS(NH!C:C,"lpg",NH!L:L,"SIDDHARTHA BISWAS"),COUNTIFS(CONV!C:C,"LPG",CONV!L:L,"SIDDHARTHA BISWAS",CONV!R:R,"Elect"),COUNTIFS(RHA!C:C,"LPG",RHA!L:L,"SIDDHARTHA BISWAS")) -> 11 | U37: =SUM(COUNTIFS(North!C:C,"lps",North!L:L,"SIDDHARTHA BISWAS"),COUNTIFS(KOAA!C:C,"lps",KOAA!L:L,"SIDDHARTHA BISWAS"),COUNTIFS(South!C:C,"lps",South!L:L,"SIDDHARTHA BISWAS"),COUNTIFS(DDJ!C:C,"lps",DDJ!L:L,"SIDDHARTHA BISWAS"),COUNTIFS(BT!C:C,"lps",BT!L:L,"SIDDHARTHA BISWAS"),COUNTIFS(NH!C:C,"lps",NH!L:L,"SIDDHARTHA BISWAS"),COUNTIFS(CONV!C:C,"LPS",CONV!L:L,"SIDDHARTHA BISWAS",CONV!R:R,"Elect"),COUNTIFS(RHA!C:C,"LPS",RHA!L:L,"SIDDHARTHA BISWAS")) -> 6 | V37: =SUM(COUNTIFS(North!C:C,"alp",North!L:L,"SIDDHARTHA BISWAS"),COUNTIFS(KOAA!C:C,"alp",KOAA!L:L,"SIDDHARTHA BISWAS"),COUNTIFS(South!C:C,"alp",South!L:L,"SIDDHARTHA BISWAS"),COUNTIFS(DDJ!C:C,"alp",DDJ!L:L,"SIDDHARTHA BISWAS"),COUNTIFS(BT!C:C,"alp",BT!L:L,"SIDDHARTHA BISWAS"),COUNTIFS(NH!C:C,"alp",NH!L:L,"SIDDHARTHA BISWAS"),COUNTIFS(CONV!C:C,"ALP",CONV!L:L,"SIDDHARTHA BISWAS"),COUNTIFS(RHA!C:C,"ALP",RHA!L:L,"SIDDHARTHA BISWAS")) -> 16 | W37: 0 | X37: =SUM(Q37:W37) -> 69 | Y37: =SUM(Q37:T37) -> 47
B38: North | C38: South | D38: KOAA | E38: DDJ | F38: NH | G38: BT | H38: RHA | I38: CP | J38: NKG | K38: HQ | L38: TOTAL | O38: 10 | P38: Bibhas Sarkar | Q38: =SUM(COUNTIFS(North!C:C,"lpm",North!L:L,"BIBHAS SARKAR"),COUNTIFS(KOAA!C:C,"lpm",KOAA!L:L,"BIBHAS SARKAR"),COUNTIFS(South!C:C,"lpm",South!L:L,"BIBHAS SARKAR"),COUNTIFS(DDJ!C:C,"lpm",DDJ!L:L,"BIBHAS SARKAR"),COUNTIFS(BT!C:C,"lpm",BT!L:L,"BIBHAS SARKAR"),COUNTIFS(NH!C:C,"lpm",NH!L:L,"BIBHAS SARKAR"),COUNTIFS(CONV!C:C,"LPM",CONV!L:L,"BIBHAS SARKAR")) -> 0 | R38: =SUM(COUNTIFS(North!C:C,"lpp(loco)",North!L:L,"BIBHAS SARKAR"),COUNTIFS(KOAA!C:C,"lpp(loco)",KOAA!L:L,"BIBHAS SARKAR"),COUNTIFS(South!C:C,"lpp(loco)",South!L:L,"BIBHAS SARKAR"),COUNTIFS(DDJ!C:C,"lpp(loco)",DDJ!L:L,"BIBHAS SARKAR"),COUNTIFS(BT!C:C,"lpp(loco)",BT!L:L,"BIBHAS SARKAR"),COUNTIFS(NH!C:C,"lpp(loco)",NH!L:L,"BIBHAS SARKAR"),COUNTIFS(CONV!C:C,"LPP(LOCO)",CONV!L:L,"BIBHAS SARKAR")) -> 0 | S38: =SUM(COUNTIFS(North!C:C,"motorman",North!L:L,"BIBHAS SARKAR"),COUNTIFS(KOAA!C:C,"motorman",KOAA!L:L,"BIBHAS SARKAR"),COUNTIFS(South!C:C,"motorman",South!L:L,"BIBHAS SARKAR"),COUNTIFS(DDJ!C:C,"motorman",DDJ!L:L,"BIBHAS SARKAR"),COUNTIFS(BT!C:C,"motorman",BT!L:L,"BIBHAS SARKAR"),COUNTIFS(NH!C:C,"motorman",NH!L:L,"BIBHAS SARKAR"),COUNTIFS(CONV!C:C,"MOTORMAN",CONV!L:L,"BIBHAS SARKAR"),COUNTIFS(RHA!C:C,"MOTORMAN",RHA!L:L,"BIBHAS SARKAR")) -> 37 | T38: =SUM(COUNTIFS(North!C:C,"lpg",North!L:L,"BIBHAS SARKAR"),COUNTIFS(KOAA!C:C,"lpg",KOAA!L:L,"BIBHAS SARKAR"),COUNTIFS(South!C:C,"lpg",South!L:L,"BIBHAS SARKAR"),COUNTIFS(DDJ!C:C,"lpg",DDJ!L:L,"BIBHAS SARKAR"),COUNTIFS(BT!C:C,"lpg",BT!L:L,"BIBHAS SARKAR"),COUNTIFS(NH!C:C,"lpg",NH!L:L,"BIBHAS SARKAR"),COUNTIFS(CONV!C:C,"LPG",CONV!L:L,"BIBHAS SARKAR",CONV!R:R,"Elect"),COUNTIFS(RHA!C:C,"LPG",RHA!L:L,"BIBHAS SARKAR")) -> 10 | U38: =SUM(COUNTIFS(North!C:C,"lps",North!L:L,"BIBHAS SARKAR"),COUNTIFS(KOAA!C:C,"lps",KOAA!L:L,"BIBHAS SARKAR"),COUNTIFS(South!C:C,"lps",South!L:L,"BIBHAS SARKAR"),COUNTIFS(DDJ!C:C,"lps",DDJ!L:L,"BIBHAS SARKAR"),COUNTIFS(BT!C:C,"lps",BT!L:L,"BIBHAS SARKAR"),COUNTIFS(NH!C:C,"lps",NH!L:L,"BIBHAS SARKAR"),COUNTIFS(CONV!C:C,"LPS",CONV!L:L,"BIBHAS SARKAR",CONV!R:R,"Elect"),COUNTIFS(RHA!C:C,"LPS",RHA!L:L,"BIBHAS SARKAR")) -> 4 | V38: =SUM(COUNTIFS(North!C:C,"alp",North!L:L,"BIBHAS SARKAR"),COUNTIFS(KOAA!C:C,"alp",KOAA!L:L,"BIBHAS SARKAR"),COUNTIFS(South!C:C,"alp",South!L:L,"BIBHAS SARKAR"),COUNTIFS(DDJ!C:C,"alp",DDJ!L:L,"BIBHAS SARKAR"),COUNTIFS(BT!C:C,"alp",BT!L:L,"BIBHAS SARKAR"),COUNTIFS(NH!C:C,"alp",NH!L:L,"BIBHAS SARKAR"),COUNTIFS(CONV!C:C,"ALP",CONV!L:L,"BIBHAS SARKAR"),COUNTIFS(RHA!C:C,"ALP",RHA!L:L,"BIBHAS SARKAR")) -> 16 | W38: 0 | X38: =SUM(Q38:W38) -> 67 | Y38: =SUM(Q38:T38) -> 47
A39: LPM | B39: =COUNTIFS(North!C:C,"LPM",North!N:N,"<="&C37) -> 15 | C39: =COUNTIFS(South!C:C,"LPM",South!N:N,"<="&C37) -> 0 | D39: =COUNTIFS(KOAA!C:C,"LPM",KOAA!N:N,"<="&C37) -> 14 | E39: =COUNTIFS(DDJ!C:C,"LPM",DDJ!N:N,"<="&C37) -> 0 | F39: =COUNTIFS(NH!C:C,"LPM",NH!N:N,"<="&C37) -> 0 | G39: =COUNTIFS(BT!C:C,"LPM",BT!N:N,"<="&C37) -> 0 | H39: =COUNTIFS(RHA!C:C,"LPM",RHA!N:N,"<="&C37) -> 0 | I39: 0 | J39: 0 | K39: 0 | L39: =SUM(B39:K39) -> 29 | O39: 11 | P39: TAPAS KR DE | Q39: =SUM(COUNTIFS(North!C:C,"lpm",North!L:L,"TAPAS KR DE"),COUNTIFS(KOAA!C:C,"lpm",KOAA!L:L,"TAPAS KR DE"),COUNTIFS(South!C:C,"lpm",South!L:L,"TAPAS KR DE"),COUNTIFS(DDJ!C:C,"lpm",DDJ!L:L,"TAPAS KR DE"),COUNTIFS(BT!C:C,"lpm",BT!L:L,"TAPAS KR DE"),COUNTIFS(NH!C:C,"lpm",NH!L:L,"TAPAS KR DE"),COUNTIFS(CONV!C:C,"LPM",CONV!L:L,"TAPAS KR DE")) -> 0 | R39: =SUM(COUNTIFS(North!C:C,"lpp(loco)",North!L:L,"TAPAS KR DE"),COUNTIFS(KOAA!C:C,"lpp(loco)",KOAA!L:L,"TAPAS KR DE"),COUNTIFS(South!C:C,"lpp(loco)",South!L:L,"TAPAS KR DE"),COUNTIFS(DDJ!C:C,"lpp(loco)",DDJ!L:L,"TAPAS KR DE"),COUNTIFS(BT!C:C,"lpp(loco)",BT!L:L,"TAPAS KR DE"),COUNTIFS(NH!C:C,"lpp(loco)",NH!L:L,"TAPAS KR DE"),COUNTIFS(CONV!C:C,"LPP(LOCO)",CONV!L:L,"TAPAS KR DE")) -> 0 | S39: =SUM(COUNTIFS(North!C:C,"motorman",North!L:L,"TAPAS KR DE"),COUNTIFS(KOAA!C:C,"motorman",KOAA!L:L,"TAPAS KR DE"),COUNTIFS(South!C:C,"motorman",South!L:L,"TAPAS KR DE"),COUNTIFS(DDJ!C:C,"motorman",DDJ!L:L,"TAPAS KR DE"),COUNTIFS(BT!C:C,"motorman",BT!L:L,"TAPAS KR DE"),COUNTIFS(NH!C:C,"motorman",NH!L:L,"TAPAS KR DE"),COUNTIFS(CONV!C:C,"MOTORMAN",CONV!L:L,"TAPAS KR DE"),COUNTIFS(RHA!C:C,"motorman",RHA!L:L,"TAPAS KR DE")) -> 36 | T39: =SUM(COUNTIFS(North!C:C,"lpg",North!L:L,"TAPAS KR DE"),COUNTIFS(KOAA!C:C,"lpg",KOAA!L:L,"TAPAS KR DE"),COUNTIFS(South!C:C,"lpg",South!L:L,"TAPAS KR DE"),COUNTIFS(DDJ!C:C,"lpg",DDJ!L:L,"TAPAS KR DE"),COUNTIFS(BT!C:C,"lpg",BT!L:L,"TAPAS KR DE"),COUNTIFS(NH!C:C,"lpg",NH!L:L,"TAPAS KR DE"),COUNTIFS(CONV!C:C,"LPG",CONV!L:L,"TAPAS KR DE",CONV!R:R,"Elect"),COUNTIFS(RHA!C:C,"LPG",RHA!L:L,"TAPAS KR DE")) -> 11 | U39: =SUM(COUNTIFS(North!C:C,"lps",North!L:L,"TAPAS KR DE"),COUNTIFS(KOAA!C:C,"lps",KOAA!L:L,"TAPAS KR DE"),COUNTIFS(South!C:C,"lps",South!L:L,"TAPAS KR DE"),COUNTIFS(DDJ!C:C,"lps",DDJ!L:L,"TAPAS KR DE"),COUNTIFS(BT!C:C,"lps",BT!L:L,"TAPAS KR DE"),COUNTIFS(NH!C:C,"lps",NH!L:L,"TAPAS KR DE"),COUNTIFS(CONV!C:C,"LPS",CONV!L:L,"TAPAS KR DE",CONV!R:R,"Elect"),COUNTIFS(RHA!C:C,"LPS",RHA!L:L,"TAPAS KR DE")) -> 6 | V39: =SUM(COUNTIFS(North!C:C,"alp",North!L:L,"TAPAS KR DE"),COUNTIFS(KOAA!C:C,"alp",KOAA!L:L,"TAPAS KR DE"),COUNTIFS(South!C:C,"alp",South!L:L,"TAPAS KR DE"),COUNTIFS(DDJ!C:C,"alp",DDJ!L:L,"TAPAS KR DE"),COUNTIFS(BT!C:C,"alp",BT!L:L,"TAPAS KR DE"),COUNTIFS(NH!C:C,"alp",NH!L:L,"TAPAS KR DE"),COUNTIFS(CONV!C:C,"ALP",CONV!L:L,"TAPAS KR DE"),COUNTIFS(RHA!C:C,"ALP",RHA!L:L,"TAPAS KR DE")) -> 17 | W39: 0 | X39: =SUM(Q39:W39) -> 70 | Y39: =SUM(Q39:T39) -> 47
A40: Motorman | B40: =COUNTIFS(North!C:C,"MOTORMAN",North!N:N,"<="&C37) -> 42 | C40: =COUNTIFS(South!C:C,"MOTORMAN",South!N:N,"<="&C37) -> 33 | D40: =COUNTIFS(KOAA!C:C,"MOTORMAN",KOAA!N:N,"<="&C37) -> 0 | E40: =COUNTIFS(DDJ!C:C,"MOTORMAN",DDJ!N:N,"<="&C37) -> 0 | F40: =COUNTIFS(NH!C:C,"MOTORMAN",NH!N:N,"<="&C37) -> 41 | G40: =COUNTIFS(BT!C:C,"MOTORMAN",BT!N:N,"<="&C37) -> 28 | H40: =COUNTIFS(RHA!C:C,"MOTORMAN",RHA!N:N,"<="&C37) -> 7 | I40: 0 | J40: 0 | K40: 0 | L40: =SUM(B40:K40) -> 151 | O40: 12 | P40: A T KHAN | Q40: =SUM(COUNTIFS(North!C:C,"lpm",North!L:L,"A T KHAN"),COUNTIFS(KOAA!C:C,"lpm",KOAA!L:L,"A T KHAN"),COUNTIFS(South!C:C,"lpm",South!L:L,"A T KHAN"),COUNTIFS(DDJ!C:C,"lpm",DDJ!L:L,"A T KHAN"),COUNTIFS(BT!C:C,"lpm",BT!L:L,"A T KHAN"),COUNTIFS(NH!C:C,"lpm",NH!L:L,"A T KHAN"),COUNTIFS(CONV!C:C,"LPM",CONV!L:L,"A T KHAN")) -> 1 | R40: =SUM(COUNTIFS(North!C:C,"lpp(loco)",North!L:L,"A T KHAN"),COUNTIFS(KOAA!C:C,"lpp(loco)",KOAA!L:L,"A T KHAN"),COUNTIFS(South!C:C,"lpp(loco)",South!L:L,"A T KHAN"),COUNTIFS(DDJ!C:C,"lpp(loco)",DDJ!L:L,"A T KHAN"),COUNTIFS(BT!C:C,"lpp(loco)",BT!L:L,"SUBHASIS MAITY"),COUNTIFS(NH!C:C,"lpp(loco)",NH!L:L,"A T KHAN"),COUNTIFS(CONV!C:C,"LPP(LOCO)",CONV!L:L,"A T KHAN")) -> 0 | S40: =SUM(COUNTIFS(North!C:C,"motorman",North!L:L,"A T KHAN"),COUNTIFS(KOAA!C:C,"motorman",KOAA!L:L,"A T KHAN"),COUNTIFS(South!C:C,"motorman",South!L:L,"A T KHAN"),COUNTIFS(DDJ!C:C,"motorman",DDJ!L:L,"A T KHAN"),COUNTIFS(BT!C:C,"motorman",BT!L:L,"A T KHAN"),COUNTIFS(NH!C:C,"motorman",NH!L:L,"A T KHAN"),COUNTIFS(CONV!C:C,"MOTORMAN",CONV!L:L,"A T KHAN"),COUNTIFS(RHA!C:C,"MOTORMAN",RHA!L:L,"A T KHAN")) -> 36 | T40: =SUM(COUNTIFS(North!C:C,"lpg",North!L:L,"A T KHAN"),COUNTIFS(KOAA!C:C,"lpg",KOAA!L:L,"A T KHAN"),COUNTIFS(South!C:C,"lpg",South!L:L,"A T KHAN"),COUNTIFS(DDJ!C:C,"lpg",DDJ!L:L,"A T KHAN"),COUNTIFS(BT!C:C,"lpg",BT!L:L,"A T KHAN"),COUNTIFS(NH!C:C,"lpg",NH!L:L,"A T KHAN"),COUNTIFS(CONV!C:C,"LPG",CONV!L:L,"A T KHAN",CONV!R:R,"Elect"),COUNTIFS(RHA!C:C,"LPG",RHA!L:L,"A T KHAN")) -> 10 | U40: =SUM(COUNTIFS(North!C:C,"lps",North!L:L,"A T KHAN"),COUNTIFS(KOAA!C:C,"lps",KOAA!L:L,"A T KHAN"),COUNTIFS(South!C:C,"lps",South!L:L,"A T KHAN"),COUNTIFS(DDJ!C:C,"lps",DDJ!L:L,"A T KHAN"),COUNTIFS(BT!C:C,"lps",BT!L:L,"A T KHAN"),COUNTIFS(NH!C:C,"lps",NH!L:L,"A T KHAN"),COUNTIFS(CONV!C:C,"LPS",CONV!L:L,"A T KHAN",CONV!R:R,"Elect"),COUNTIFS(RHA!C:C,"LPS",RHA!L:L,"A T KHAN")) -> 7 | V40: =SUM(COUNTIFS(North!C:C,"alp",North!L:L,"A T KHAN"),COUNTIFS(KOAA!C:C,"alp",KOAA!L:L,"A T KHAN"),COUNTIFS(South!C:C,"alp",South!L:L,"A T KHAN"),COUNTIFS(DDJ!C:C,"alp",DDJ!L:L,"A T KHAN"),COUNTIFS(BT!C:C,"alp",BT!L:L,"A T KHAN"),COUNTIFS(NH!C:C,"alp",NH!L:L,"A T KHAN"),COUNTIFS(CONV!C:C,"ALP",CONV!L:L,"A T KHAN"),COUNTIFS(RHA!C:C,"ALP",RHA!L:L,"A T KHAN")) -> 14 | W40: 0 | X40: =SUM(Q40:W40) -> 68 | Y40: =SUM(Q40:T40) -> 47
A41: LPP(Loco) | B41: =COUNTIFS(North!C:C,"LPP(LOCO)",North!N:N,"<="&C37) -> 5 | C41: =COUNTIFS(South!C:C,"LPP(LOCO)",South!N:N,"<="&C37) -> 0 | D41: =COUNTIFS(KOAA!C:C,"LPP(LOCO)",KOAA!N:N,"<="&C37) -> 0 | E41: =COUNTIFS(DDJ!C:C,"LPP(LOCO)",DDJ!N:N,"<="&C37) -> 0 | F41: =COUNTIFS(NH!C:C,"LPP(LOCO)",NH!N:N,"<="&C37) -> 0 | G41: =COUNTIFS(BT!C:C,"LPP(LOCO)",BT!N:N,"<="&C37) -> 0 | H41: =COUNTIFS(RHA!C:C,"LPP(LOCO)",RHA!N:N,"<="&C37) -> 0 | I41: 0 | J41: 0 | K41: 0 | L41: =SUM(B41:K41) -> 5 | O41: 13 | P41: SUSOVAN KAR | Q41: =SUM(COUNTIFS(North!C:C,"lpm",North!L:L,"SUSOVAN KAR"),COUNTIFS(KOAA!C:C,"lpm",KOAA!L:L,"SUSOVAN KAR"),COUNTIFS(South!C:C,"lpm",South!L:L,"SUSOVAN KAR"),COUNTIFS(DDJ!C:C,"lpm",DDJ!L:L,"SUSOVAN KAR"),COUNTIFS(BT!C:C,"lpm",BT!L:L,"SUSOVAN KAR"),COUNTIFS(NH!C:C,"lpm",NH!L:L,"SUSOVAN KAR"),COUNTIFS(CONV!C:C,"LPM",CONV!L:L,"SUSOVAN KAR")) -> 0 | R41: =SUM(COUNTIFS(North!C:C,"lpp(loco)",North!L:L,"SUSOVAN KAR"),COUNTIFS(KOAA!C:C,"lpp(loco)",KOAA!L:L,"SUSOVAN KAR"),COUNTIFS(South!C:C,"lpp(loco)",South!L:L,"SUSOVAN KAR"),COUNTIFS(DDJ!C:C,"lpp(loco)",DDJ!L:L,"SUSOVAN KAR"),COUNTIFS(BT!C:C,"lpp(loco)",BT!L:L,"SUSOVAN KAR"),COUNTIFS(NH!C:C,"lpp(loco)",NH!L:L,"SUSOVAN KAR"),COUNTIFS(CONV!C:C,"LPP(LOCO)",CONV!L:L,"SUSOVAN KAR")) -> 0 | S41: =SUM(COUNTIFS(North!C:C,"motorman",North!L:L,"SUSOVAN KAR"),COUNTIFS(KOAA!C:C,"motorman",KOAA!L:L,"SUSOVAN KAR"),COUNTIFS(South!C:C,"motorman",South!L:L,"SUSOVAN KAR"),COUNTIFS(DDJ!C:C,"motorman",DDJ!L:L,"SUSOVAN KAR"),COUNTIFS(BT!C:C,"motorman",BT!L:L,"SUSOVAN KAR"),COUNTIFS(NH!C:C,"motorman",NH!L:L,"SUSOVAN KAR"),COUNTIFS(CONV!C:C,"MOTORMAN",CONV!L:L,"susovan kar"),COUNTIFS(RHA!C:C,"MOTORMAN",RHA!L:L,"SUSOVAN KAR")) -> 36 | T41: =SUM(COUNTIFS(North!C:C,"lpg",North!L:L,"SUSOVAN KAR"),COUNTIFS(KOAA!C:C,"lpg",KOAA!L:L,"SUSOVAN KAR"),COUNTIFS(South!C:C,"lpg",South!L:L,"SUSOVAN KAR"),COUNTIFS(DDJ!C:C,"lpg",DDJ!L:L,"SUSOVAN KAR"),COUNTIFS(BT!C:C,"lpg",BT!L:L,"SUSOVAN KAR"),COUNTIFS(NH!C:C,"lpg",NH!L:L,"SUSOVAN KAR"),COUNTIFS(CONV!C:C,"LPG",CONV!L:L,"SUSOVAN KAR",CONV!R:R,"Elect"),COUNTIFS(RHA!C:C,"LPG",RHA!L:L,"SUSOVAN KAR")) -> 10 | U41: =SUM(COUNTIFS(North!C:C,"lps",North!L:L,"SUSOVAN KAR"),COUNTIFS(KOAA!C:C,"lps",KOAA!L:L,"SUSOVAN KAR"),COUNTIFS(South!C:C,"lps",South!L:L,"SUSOVAN KAR"),COUNTIFS(DDJ!C:C,"lps",DDJ!L:L,"SUSOVAN KAR"),COUNTIFS(BT!C:C,"lps",BT!L:L,"SUSOVAN KAR"),COUNTIFS(NH!C:C,"lps",NH!L:L,"SUSOVAN KAR"),COUNTIFS(CONV!C:C,"LPS",CONV!L:L,"SUSOVAN KAR",CONV!R:R,"Elect"),COUNTIFS(RHA!C:C,"LPS",RHA!L:L,"SUSOVAN KAR")) -> 6 | V41: =SUM(COUNTIFS(North!C:C,"alp",North!L:L,"SUSOVAN KAR"),COUNTIFS(KOAA!C:C,"alp",KOAA!L:L,"SUSOVAN KAR"),COUNTIFS(South!C:C,"alp",South!L:L,"SUSOVAN KAR"),COUNTIFS(DDJ!C:C,"alp",DDJ!L:L,"SUSOVAN KAR"),COUNTIFS(BT!C:C,"alp",BT!L:L,"SUSOVAN KAR"),COUNTIFS(NH!C:C,"alp",NH!L:L,"SUSOVAN KAR"),COUNTIFS(CONV!C:C,"ALP",CONV!L:L,"SUSOVAN KAR"),COUNTIFS(RHA!C:C,"ALP",RHA!L:L,"SUSOVAN KAR")) -> 15 | W41: 0 | X41: =SUM(Q41:W41) -> 67 | Y41: =SUM(Q41:T41) -> 46
...

Sheet METRO 
B1: N a m e | C1: SC/ST | D1: Design. | E1: P.F.No. | F1: Date of Birth | G1: DOR | H1: Date of Apptt. | I1: Date of Prom. as LPG | J1: Apt Test | K1: Prom. Training | L1: Working at
A2: 1 | B2: NABIN KR. SAHA | C2: SC | D2: LPP | E2: 540713 | F2: 14.01.71 | G2: 47879 | H2: 19.07.99 | I2: 10.06.10 | J2: 06.09.12 (M/Man) | K2: As lien.
A3: 2 | B3: DEBBRATA RAY | C3: SC | D3: LPP | E3: 5407126 | F3: 25.04.66 | G3: 46142 | H3: 31.05.99 | I3: 10.06.10 | J3: 18.09.19 (M/Man) | K3: As lien.
A4: 3 | B4: SUBHAJIT BANERJEE | C4: UR | D4: LPP | E4: 5395252 | F4: 17.02.67 | G4: 46446 | H4: 18.12.95 | I4: 16.03.12 | J4: 18.09.19 (M/Man) | K4: As lien.
A5: 4 | B5: GADADHAR SARKAR | C5: UR | D5: LPP | E5: 5395264 | F5: 17.09.67 | G5: 46660 | H5: 18.12.95 | I5: 31.10.12 | J5: 18.09.19 (M/Man) | K5: As lien.
A6: 5 | B6: BIPLAB KR. MALLICK | C6: SC | D6: LPP | E6: 7427967 | F6: 05.04.72 | G6: 48334 | H6: 24.04.2000 | I6: 03.01.13 | J6: 18.09.19 (M/Man) | K6: As lien.
A7: 6 | B7: SANAT KR. MAITY | C7: UR | D7: LPP | E7: 725353 | F7: 15.10.73 | G7: 48883 | H7: 05.06.01 | I7: 19.02.13 | J7: 18.09.19 (M/Man) | K7: As lien.
A8: 7 | B8: BIJAY SAHA | C8: UR | D8: LPP | E8: 5419256 | F8: 25.05.76 | G8: 49826 | H8: 09.08.02 | I8: 30.09.15 | J8: 18.09.19 (M/Man) | K8: As lien.
A9: 8 | B9: MANAS DAS | C9: UR | D9: LPP | E9: 50205419165 | F9: 09.03.76 | G9: 49765 | H9: 01.08.02 | I9: 10.01.17 | J9: 18.09.19 (M/Man) | K9: As lien.
A10: 9 | B10: Sanjay Kumar -II | C10: SC | D10: LPP | E10: 5520435 | F10: 05.12.77 | G10: 50405 | H10: 25.02.03 | I10: 03.10.19 | J10: 10.07.18 (LPG) | K10: As lien. | L10: Promoted to M/Man by M/Railway.
A11: 10 | B11: Abhijit Maitra | C11: SC | D11: LPP | E11: 5866546 | F11: 24.12.69 | G11: 47483 | H11: 07.03.00 | I11: 03.10.19 | J11: 10.07.18 (LPG) | K11: As lien. | L11: Promoted to M/Man by M/Railway.
A12: 11 | B12: Mithun Biswas | C12: SC | D12: LPP | E12: 5562340 | F12: 15.01.86 | G12: 53358 | H12: 22.03.10 | I12: 18.09.19 | J12: 10.07.18 (LPG) | K12: As lien. | L12: Promoted to M/Man by M/Railway.
A13: 12 | B13: Koushik Mondal | C13: SC | D13: LPP | E13: 62099710 | F13: 22.04.84 | G13: 52717 | H13: 03.08.09 | I13: 03.10.19 | J13: 10.07.18 (LPG) | K13: As lien. | L13: Promoted to M/Man by M/Railway.
A14: 13 | B14: Avijit Kirtania | C14: SC | D14: LPP | E14: 5569096 | F14: 12.01.82 | G14: 51897 | H14: 17.10.11 | I14: 03.10.19 | J14: 27.07.18 (LPG) | K14: As lien. | L14: Promoted to M/Man by M/Railway.
A15: 14 | B15: Mithun Debnath | C15: UR | D15: LPP | E15: 5559054 | F15: 05.03.83 | G15: 52382 | H15: 23.12.09 | I15: 03.10.19 | J15: 27.07.18 (LPG) | K15: As lien. | L15: Promoted to M/Man by M/Railway.
A16: 15 | B16: RABINDRA KUMAR | C16: UR | D16: LPP | E16: 50205569205 | F16: 04.02.87 | G16: 53751 | H16: 17.10.11 | I16: 03.10.19 | J16: 07.11.18 (LPG) | K16: As lien. | L16: Promoted to M/Man by M/Railway.
A17: 16 | B17: RUDRAK DAS | C17: UR | D17: LPP | E17: 50200036110 | F17: 01.01.76 | G17: 50040 | H17: 10.05.06 | I17: 03.10.19 | J17: 14.11.18 (LPG) | K17: As lien. | L17: Promoted to M/Man by M/Railway.
A18: 17 | B18: PRABIR KUMAR SARDAR | C18: UR | D18: LPP | E18: 50200065780 | F18: 26.11.75 | G18: 49643 | H18: 05.03.07 | I18: 03.10.19 | J18: 14.11.18 (LPG) | K18: As lien. | L18: Promoted to M/Man by M/Railway.
A19: 18 | B19: BARUN KUMAR MIDYA | C19: UR | D19: LPP | E19: 50200036867 | F19: 25.11.76 | G19: 50009 | H19: 09.05.06 | I19: 03.10.19 | J19: 14.11.18 (LPG) | K19: As lien. | L19: Promoted to M/Man by M/Railway.
A20: 19 | B20: PARIMAL DAS | C20: SC | D20: LPP | E20: 5421068 | F20: 15.09.71 | G20: 48121 | H20: 28.02.03 | I20: 30.09.15 | J20: 03.08.20 (M/Man) | K20: As lien.
A21: 20 | B21: BIKASH KAR | C21: UR | D21: LPP | E21: 5419220 | F21: 21.01.74 | G21: 48975 | H21: 01.08.02 | I21: 30.09.15 | J21: 03.08.20 (M/Man) | K21: As lien.
A22: 21 | B22: PALLAB PATRA | C22: UR | D22: LPP | E22: 50205522658 | F22: 22.01.77 | G22: 50071 | H22: 05.07.06 | I22: 10.01.17 | J22: 03.08.20 (M/Man) | K22: As lien.
A23: 22 | B23: SUDIP PAL | C23: UR | D23: LPP | E23: 50205522663 | F23: 21.01.81 | G23: 51532 | H23: 05.07.06 | I23: 10.01.17 | J23: 03.08.20 (M/Man) | K23: As lien.
A24: 23 | B24: Varun Kumar | C24: UR | D24: LPP | E24: 5558736 | F24: 04.02.87 | G24: 53751 | H24: 19.10.09 | I24: 10.08.17 | J24: 03.08.20 (M/Man) | K24: As lien.
A25: 24 | B25: Arup Kumar Mondal | C25: UR | D25: LPP | E25: 5558773 | F25: 02.11.80 | G25: 51470 | H25: 19.10.09 | I25: 10.08.17 | J25: 03.08.20 (M/Man) | K25: As lien.
A26: 25 | B26: Manish Kumar | C26: UR | D26: LPP | E26: 5558797 | F26: 07.01.83 | G26: 52262 | H26: 19.10.09 | I26: 10.08.17 | J26: 03.08.20 (M/Man) | K26: As lien.
A27: 26 | B27: Gourav Kumar | C27: UR | D27: LPP | E27: 5558815 | F27: 01.02.87 | G27: 53751 | H27: 19.10.09 | I27: 10.08.17 | J27: 03.08.20 (M/Man) | K27: As lien.
A28: 27 | B28: Suman Kumar Singh | C28: UR | D28: LPP | E28: 5559017 | F28: 24.10.87 | G28: 53996 | H28: 21.12.09 | I28: 10.08.17 | J28: 03.08.20 (M/Man) | K28: As lien.
A29: 28 | B29: Sanjib Seal | C29: UR | D29: LPP | E29: 51901 | F29: 05.04.78 | G29: 50525 | H29: 05.07.06 | I29: 31.08.17 | J29: 03.08.20 (M/Man) | K29: As lien.
A30: 29 | B30: Joydip Ghosh-II | C30: UR | D30: LPP | E30: 12131325 | F30: 11.04.78 | G30: 50525 | H30: 05.06.01 | I30: 20.10.17 | J30: 03.08.20 (M/Man) | K30: As lien.
A31: 30 | B31: Samiran Halder | C31: UR | D31: LPP | E31: 12124760 | F31: 17.09.70 | G31: 47756 | H31: 31.05.99 | I31: 20.10.17 | J31: 03.08.20 (M/Man) | K31: As lien.
... A37: 36 | B37: DEBASISH PAN | C37: UR | D37: LPM | E37: 5419177 | F37: 22.02.75 | G37: 49368 | H37: 01.08.02 | I37: 18.02.20 | J37: 03.08.20 (M/Man) | K37: As lien.
A38: 37 | B38: SRIRUP KUNDU | C38: UR | D38: LPP | E38: 50205607243 | F38: 30524 | G38: 52443 | K38: As lien. | M38: CC(R) NORTH | N38: SWAPAN KUMAR MONDAL | Q38: 45924 | R38: 45559 | S38: 45527 | V38: https://drive.google.com/file/d/1foEPtOsuwxEnIkPtVsjRp0HZY15nlyLz/view?usp=sharing | X38: =LEN(E38) -> 11 | Y38: =INT((TODAY()-F38)/365) -> 42
